Workbook

Sheet README
A1: Fault-injection campaign — M2 (ResNet-20), exported ONNX bundle with D2 SVDD monitor
A3: What was run
A4: 10 fault configurations × 10 repetitions. Each repetition flips a fresh, seeded random set of bits (seed = 1000 × config number + repetition − 1) in the weights of artifacts/deploy/m2_fp32_default_seed0/model.onnx, then runs the 200 bundled CIFAR-10 test pictures (20 per class, 10 classes) through the corrupted model.
A5: Injection is the bundle UI's own code (sections 3–4), driven automatically in a headless browser with ONNX Runtime Web. The model is restored between repetitions; flips never accumulate across repetitions.
A6: The monitor is the joint SVDD (D2) inside model.onnx, thresholds fixed on clean_cal at export. Headline sheets use the false-alarm setting α = 1 % (the UI default); 'Runs' also holds α = 5 % and 0.1 %.
A8: How each metric is defined (per configuration, repetition and class)
A9: Positives: the class's 20 pictures through the corrupted model (should be flagged). Negatives: the same 20 pictures through the model before flips, in the same weight format (should not be flagged).
A10: Recall (detection rate) = TP / (TP + FN). Precision = TP / (TP + FP), blank when nothing was flagged. F1 = 2·TP / (2·TP + FP + FN). False-alarm rate = FP / (FP + TN).
A11: Mean and SD are across the 10 repetitions (sample SD, n − 1). Precision's mean and SD use only repetitions where it is defined; column N says how many.
A12: Class 'ALL' pools the 200 pictures of a repetition.
A14: Read before using these numbers
A15: • False-alarm rate has SD 0 by construction: it is measured on the unflipped model, which is the same in every repetition of a configuration.
... A26: Configurations — the 10 settings. Flips — every bit flipped, per run, for reproduction.

Sheet Overview
A1: Detection per configuration — all 10 classes pooled (200 pictures per run), 10 repetitions, α = 1 %
A3: Config | B3: Format | C3: Where | D3: Which bit | E3: Flips | F3: Recall mean | G3: Recall SD | H3: Precision mean | I3: Precision SD | J3: Precision N | K3: F1 mean | L3: F1 SD | M3: False-alarm rate mean | N3: False-alarm rate SD | O3: Answers changed (of 200), mean | P3: Recall when answer changed | Q3: Recall when answer unchanged | R3: Accuracy after (mean) | S3: Runs with recall ≥ 50 %
A4: C01 | B4: FP32 | C4: early | D4: Sign bit | E4: 16 | F4: =Recall!Q12 -> 0.0055 | G4: =Recall!R12 -> 0.0028382311 | H4: =Precision!Q12 -> 0.48333333 | I4: =Precision!R12 -> 0.18341749 | J4: =Precision!S12 -> 10 | K4: =F1!Q12 -> 0.01087158 | L4: =F1!R12 -> 0.0055859364 | M4: ='False alarms'!Q12 -> 0.005 | N4: ='False alarms'!R12 -> 0 | O4: =AVERAGEIFS(Runs!$R$2:$R$3301,Runs!$A$2:$A$3301,"C01",Runs!$G$2:$G$3301,"ALL",Runs!$H$2:$H$3301,0.01) -> 6.8 | P4: =IFERROR(AVERAGEIFS(Runs!$S$2:$S$3301,Runs!$A$2:$A$3301,"C01",Runs!$G$2:$G$3301,"ALL",Runs!$H$2:$H$3301,0.01),"") -> 0 | Q4: =IFERROR(AVERAGEIFS(Runs!$T$2:$T$3301,Runs!$A$2:$A$3301,"C01",Runs!$G$2:$G$3301,"ALL",Runs!$H$2:$H$3301,0.01),"") -> 0.0056947017 | R4: =AVERAGEIFS(Runs!$V$2:$V$3301,Runs!$A$2:$A$3301,"C01",Runs!$G$2:$G$3301,"ALL",Runs!$H$2:$H$3301,0.01) -> 0.884 | S4: =COUNTIF(Recall!G12:P12,">=0.5") -> 0
A5: C02 | B5: FP32 | C5: early | D5: Exponent, top bits (drastic) | E5: 1 | F5: =Recall!Q23 -> 0.204 | G5: =Recall!R23 -> 0.41952884 | H5: =Precision!Q23 -> 0.59900498 | I5: =Precision!R23 -> 0.20872081 | J5: =Precision!S23 -> 10 | K5: =F1!Q23 -> 0.20742204 | L5: =F1!R23 -> 0.41641093 | M5: ='False alarms'!Q23 -> 0.005 | N5: ='False alarms'!R23 -> 0 | O5: =AVERAGEIFS(Runs!$R$2:$R$3301,Runs!$A$2:$A$3301,"C02",Runs!$G$2:$G$3301,"ALL",Runs!$H$2:$H$3301,0.01) -> 36.5 | P5: =IFERROR(AVERAGEIFS(Runs!$S$2:$S$3301,Runs!$A$2:$A$3301,"C02",Runs!$G$2:$G$3301,"ALL",Runs!$H$2:$H$3301,0.01),"") -> 0.4 | Q5: =IFERROR(AVERAGEIFS(Runs!$T$2:$T$3301,Runs!$A$2:$A$3301,"C02",Runs!$G$2:$G$3301,"ALL",Runs!$H$2:$H$3301,0.01),"") -> 0.20402292 | R5: =AVERAGEIFS(Runs!$V$2:$V$3301,Runs!$A$2:$A$3301,"C02",Runs!$G$2:$G$3301,"ALL",Runs!$H$2:$H$3301,0.01) -> 0.723 | S5: =COUNTIF(Recall!G23:P23,">=0.5") -> 2
A6: C03 | B6: FP32 | C6: middle | D6: Exponent, top bits (drastic) | E6: 4 | F6: =Recall!Q34 -> 0.5025 | G6: =Recall!R34 -> 0.52441105 | H6: =Precision!Q34 -> 0.74751244 | I6: =Precision!R34 -> 0.26090102 | J6: =Precision!S34 -> 10 | K6: =F1!Q34 -> 0.50370361 | L6: =F1!R34 -> 0.52051367 | M6: ='False alarms'!Q34 -> 0.005 | N6: ='False alarms'!R34 -> 0 | O6: =AVERAGEIFS(Runs!$R$2:$R$3301,Runs!$A$2:$A$3301,"C03",Runs!$G$2:$G$3301,"ALL",Runs!$H$2:$H$3301,0.01) -> 89.5 | P6: =IFERROR(AVERAGEIFS(Runs!$S$2:$S$3301,Runs!$A$2:$A$3301,"C03",Runs!$G$2:$G$3301,"ALL",Runs!$H$2:$H$3301,0.01),"") -> 0.625 | Q6: =IFERROR(AVERAGEIFS(Runs!$T$2:$T$3301,Runs!$A$2:$A$3301,"C03",Runs!$G$2:$G$3301,"ALL",Runs!$H$2:$H$3301,0.01),"") -> 0.50252802 | R6: =AVERAGEIFS(Runs!$V$2:$V$3301,Runs!$A$2:$A$3301,"C03",Runs!$G$2:$G$3301,"ALL",Runs!$H$2:$H$3301,0.01) -> 0.4935 | S6: =COUNTIF(Recall!G34:P34,">=0.5") -> 5
A7: C04 | B7: FP32 | C7: late | D7: Exponent, top bits (drastic) | E7: 1 | F7: =Recall!Q45 -> 0.2 | G7: =Recall!R45 -> 0.41120419 | H7: =Precision!Q45 -> 0.59898435 | I7: =Precision!R45 -> 0.20867734 | J7: =Precision!S45 -> 10 | K7: =F1!Q45 -> 0.20538134 | L7: =F1!R45 -> 0.41213683 | M7: ='False alarms'!Q45 -> 0.005 | N7: ='False alarms'!R45 -> 0 | O7: =AVERAGEIFS(Runs!$R$2:$R$3301,Runs!$A$2:$A$3301,"C04",Runs!$G$2:$G$3301,"ALL",Runs!$H$2:$H$3301,0.01) -> 35.6 | P7: =IFERROR(AVERAGEIFS(Runs!$S$2:$S$3301,Runs!$A$2:$A$3301,"C04",Runs!$G$2:$G$3301,"ALL",Runs!$H$2:$H$3301,0.01),"") -> 1 | Q7: =IFERROR(AVERAGEIFS(Runs!$T$2:$T$3301,Runs!$A$2:$A$3301,"C04",Runs!$G$2:$G$3301,"ALL",Runs!$H$2:$H$3301,0.01),"") -> 0.16921739 | R7: =AVERAGEIFS(Runs!$V$2:$V$3301,Runs!$A$2:$A$3301,"C04",Runs!$G$2:$G$3301,"ALL",Runs!$H$2:$H$3301,0.01) -> 0.726 | S7: =COUNTIF(Recall!G45:P45,">=0.5") -> 2
A8: C05 | B8: FP32 | C8: late | D8: Exponent, low bits | E8: 16 | F8: =Recall!Q56 -> 0.017 | G8: =Recall!R56 -> 0.02287648 | H8: =Precision!Q56 -> 0.61785714 | I8: =Precision!R56 -> 0.17446333 | J8: =Precision!S56 -> 10 | K8: =F1!Q56 -> 0.032408372 | L8: =F1!R56 -> 0.04267676 | M8: ='False alarms'!Q56 -> 0.005 | N8: ='False alarms'!R56 -> 0 | O8: =AVERAGEIFS(Runs!$R$2:$R$3301,Runs!$A$2:$A$3301,"C05",Runs!$G$2:$G$3301,"ALL",Runs!$H$2:$H$3301,0.01) -> 6.3 | P8: =IFERROR(AVERAGEIFS(Runs!$S$2:$S$3301,Runs!$A$2:$A$3301,"C05",Runs!$G$2:$G$3301,"ALL",Runs!$H$2:$H$3301,0.01),"") -> 0.015458937 | Q8: =IFERROR(AVERAGEIFS(Runs!$T$2:$T$3301,Runs!$A$2:$A$3301,"C05",Runs!$G$2:$G$3301,"ALL",Runs!$H$2:$H$3301,0.01),"") -> 0.017082355 | R8: =AVERAGEIFS(Runs!$V$2:$V$3301,Runs!$A$2:$A$3301,"C05",Runs!$G$2:$G$3301,"ALL",Runs!$H$2:$H$3301,0.01) -> 0.8745 | S8: =COUNTIF(Recall!G56:P56,">=0.5") -> 0
A9: C06 | B9: FP32 | C9: middle | D9: Mantissa, high bits | E9: 16 | F9: =Recall!Q67 -> 0.005 | G9: =Recall!R67 -> 0 | H9: =Precision!Q67 -> 0.5 | I9: =Precision!R67 -> 0 | J9: =Precision!S67 -> 10 | K9: =F1!Q67 -> 0.0099009901 | L9: =F1!R67 -> 0 | M9: ='False alarms'!Q67 -> 0.005 | N9: ='False alarms'!R67 -> 0 | O9: =AVERAGEIFS(Runs!$R$2:$R$3301,Runs!$A$2:$A$3301,"C06",Runs!$G$2:$G$3301,"ALL",Runs!$H$2:$H$3301,0.01) -> 0.2 | P9: =IFERROR(AVERAGEIFS(Runs!$S$2:$S$3301,Runs!$A$2:$A$3301,"C06",Runs!$G$2:$G$3301,"ALL",Runs!$H$2:$H$3301,0.01),"") -> 0 | Q9: =IFERROR(AVERAGEIFS(Runs!$T$2:$T$3301,Runs!$A$2:$A$3301,"C06",Runs!$G$2:$G$3301,"ALL",Runs!$H$2:$H$3301,0.01),"") -> 0.0050050251 | R9: =AVERAGEIFS(Runs!$V$2:$V$3301,Runs!$A$2:$A$3301,"C06",Runs!$G$2:$G$3301,"ALL",Runs!$H$2:$H$3301,0.01) -> 0.8805 | S9: =COUNTIF(Recall!G67:P67,">=0.5") -> 0
A10: C07 | B10: FP32 | C10: late | D10: Mantissa, low bits (subtle) | E10: 16 | F10: =Recall!Q78 -> 0.005 | G10: =Recall!R78 -> 0 | H10: =Precision!Q78 -> 0.5 | I10: =Precision!R78 -> 0 | J10: =Precision!S78 -> 10 | K10: =F1!Q78 -> 0.0099009901 | L10: =F1!R78 -> 0 | M10: ='False alarms'!Q78 -> 0.005 | N10: ='False alarms'!R78 -> 0 | O10: =AVERAGEIFS(Runs!$R$2:$R$3301,Runs!$A$2:$A$3301,"C07",Runs!$G$2:$G$3301,"ALL",Runs!$H$2:$H$3301,0.01) -> 0 | P10: =IFERROR(AVERAGEIFS(Runs!$S$2:$S$3301,Runs!$A$2:$A$3301,"C07",Runs!$G$2:$G$3301,"ALL",Runs!$H$2:$H$3301,0.01),"") | Q10: =IFERROR(AVERAGEIFS(Runs!$T$2:$T$3301,Runs!$A$2:$A$3301,"C07",Runs!$G$2:$G$3301,"ALL",Runs!$H$2:$H$3301,0.01),"") -> 0.005 | R10: =AVERAGEIFS(Runs!$V$2:$V$3301,Runs!$A$2:$A$3301,"C07",Runs!$G$2:$G$3301,"ALL",Runs!$H$2:$H$3301,0.01) -> 0.88 | S10: =COUNTIF(Recall!G78:P78,">=0.5") -> 0
A11: C08 | B11: INT8 | C11: early | D11: Sign bit | E11: 4 | F11: =Recall!Q89 -> 0.0055 | G11: =Recall!R89 -> 0.0028382311 | H11: =Precision!Q89 -> 0.48333333 | I11: =Precision!R89 -> 0.18341749 | J11: =Precision!S89 -> 10 | K11: =F1!Q89 -> 0.01087158 | L11: =F1!R89 -> 0.0055859364 | M11: ='False alarms'!Q89 -> 0.005 | N11: ='False alarms'!R89 -> 0 | O11: =AVERAGEIFS(Runs!$R$2:$R$3301,Runs!$A$2:$A$3301,"C08",Runs!$G$2:$G$3301,"ALL",Runs!$H$2:$H$3301,0.01) -> 5.8 | P11: =IFERROR(AVERAGEIFS(Runs!$S$2:$S$3301,Runs!$A$2:$A$3301,"C08",Runs!$G$2:$G$3301,"ALL",Runs!$H$2:$H$3301,0.01),"") -> 0.016666667 | Q11: =IFERROR(AVERAGEIFS(Runs!$T$2:$T$3301,Runs!$A$2:$A$3301,"C08",Runs!$G$2:$G$3301,"ALL",Runs!$H$2:$H$3301,0.01),"") -> 0.0051101284 | R11: =AVERAGEIFS(Runs!$V$2:$V$3301,Runs!$A$2:$A$3301,"C08",Runs!$G$2:$G$3301,"ALL",Runs!$H$2:$H$3301,0.01) -> 0.874 | S11: =COUNTIF(Recall!G89:P89,">=0.5") -> 0
A12: C09 | B12: INT8 | C12: late | D12: Top magnitude bit | E12: 16 | F12: =Recall!Q100 -> 0.007 | G12: =Recall!R100 -> 0.0063245553 | H12: =Precision!Q100 -> 0.53333333 | I12: =Precision!R100 -> 0.10540926 | J12: =Precision!S100 -> 10 | K12: =F1!Q100 -> 0.01376526 | L12: =F1!R100 -> 0.012219894 | M12: ='False alarms'!Q100 -> 0.005 | N12: ='False alarms'!R100 -> 0 | O12: =AVERAGEIFS(Runs!$R$2:$R$3301,Runs!$A$2:$A$3301,"C09",Runs!$G$2:$G$3301,"ALL",Runs!$H$2:$H$3301,0.01) -> 2 | P12: =IFERROR(AVERAGEIFS(Runs!$S$2:$S$3301,Runs!$A$2:$A$3301,"C09",Runs!$G$2:$G$3301,"ALL",Runs!$H$2:$H$3301,0.01),"") -> 0 | Q12: =IFERROR(AVERAGEIFS(Runs!$T$2:$T$3301,Runs!$A$2:$A$3301,"C09",Runs!$G$2:$G$3301,"ALL",Runs!$H$2:$H$3301,0.01),"") -> 0.0070915533 | R12: =AVERAGEIFS(Runs!$V$2:$V$3301,Runs!$A$2:$A$3301,"C09",Runs!$G$2:$G$3301,"ALL",Runs!$H$2:$H$3301,0.01) -> 0.884 | S12: =COUNTIF(Recall!G100:P100,">=0.5") -> 0
A13: C10 | B13: FP16 | C13: early | D13: Sign bit | E13: 16 | F13: =Recall!Q111 -> 0.0055 | G13: =Recall!R111 -> 0.0028382311 | H13: =Precision!Q111 -> 0.48333333 | I13: =Precision!R111 -> 0.18341749 | J13: =Precision!S111 -> 10 | K13: =F1!Q111 -> 0.01087158 | L13: =F1!R111 -> 0.0055859364 | M13: ='False alarms'!Q111 -> 0.005 | N13: ='False alarms'!R111 -> 0 | O13: =AVERAGEIFS(Runs!$R$2:$R$3301,Runs!$A$2:$A$3301,"C10",Runs!$G$2:$G$3301,"ALL",Runs!$H$2:$H$3301,0.01) -> 4.1 | P13: =IFERROR(AVERAGEIFS(Runs!$S$2:$S$3301,Runs!$A$2:$A$3301,"C10",Runs!$G$2:$G$3301,"ALL",Runs!$H$2:$H$3301,0.01),"") -> 0 | Q13: =IFERROR(AVERAGEIFS(Runs!$T$2:$T$3301,Runs!$A$2:$A$3301,"C10",Runs!$G$2:$G$3301,"ALL",Runs!$H$2:$H$3301,0.01),"") -> 0.0056257869 | R13: =AVERAGEIFS(Runs!$V$2:$V$3301,Runs!$A$2:$A$3301,"C10",Runs!$G$2:$G$3301,"ALL",Runs!$H$2:$H$3301,0.01) -> 0.8825 | S13: =COUNTIF(Recall!G111:P111,">=0.5") -> 0
A15: Green = linked from the per-metric sheets; other columns compute from 'Runs'. 'Recall when answer changed/unchanged' averages only runs where such pictures exist.
A16: Accuracy before flips: 88.0 % for FP32, INT8 and FP16 alike on these 200 pictures. False-alarm rate is measured on the model before flips, so its SD is 0.
A17: Exponent-top configurations (C02–C04) are all-or-nothing per run; 'Runs with recall ≥ 50 %' shows how many of the 10 blew the network up.

Sheet Recall by class
A1: Mean recall per class (10 repetitions, α = 1 %) — links to the 'Recall' sheet
A3: Config | B3: Format | C3: Where | D3: Which bit | E3: Flips | F3: airplane | G3: automobile | H3: bird | I3: cat | J3: deer | K3: dog | L3: frog | M3: horse | N3: ship | O3: truck | P3: ALL
A4: C01 | B4: FP32 | C4: early | D4: Sign bit | E4: 16 | F4: =Recall!Q2 -> 0 | G4: =Recall!Q3 -> 0.005 | H4: =Recall!Q4 -> 0 | I4: =Recall!Q5 -> 0 | J4: =Recall!Q6 -> 0 | K4: =Recall!Q7 -> 0 | L4: =Recall!Q8 -> 0.015 | M4: =Recall!Q9 -> 0 | N4: =Recall!Q10 -> 0 | O4: =Recall!Q11 -> 0.035 | P4: =Recall!Q12 -> 0.0055
A5: C02 | B5: FP32 | C5: early | D5: Exponent, top bits (drastic) | E5: 1 | F5: =Recall!Q13 -> 0.2 | G5: =Recall!Q14 -> 0.2 | H5: =Recall!Q15 -> 0.2 | I5: =Recall!Q16 -> 0.2 | J5: =Recall!Q17 -> 0.2 | K5: =Recall!Q18 -> 0.2 | L5: =Recall!Q19 -> 0.2 | M5: =Recall!Q20 -> 0.2 | N5: =Recall!Q21 -> 0.2 | O5: =Recall!Q22 -> 0.24 | P5: =Recall!Q23 -> 0.204
A6: C03 | B6: FP32 | C6: middle | D6: Exponent, top bits (drastic) | E6: 4 | F6: =Recall!Q24 -> 0.5 | G6: =Recall!Q25 -> 0.5 | H6: =Recall!Q26 -> 0.5 | I6: =Recall!Q27 -> 0.5 | J6: =Recall!Q28 -> 0.5 | K6: =Recall!Q29 -> 0.5 | L6: =Recall!Q30 -> 0.5 | M6: =Recall!Q31 -> 0.5 | N6: =Recall!Q32 -> 0.5 | O6: =Recall!Q33 -> 0.525 | P6: =Recall!Q34 -> 0.5025
A7: C04 | B7: FP32 | C7: late | D7: Exponent, top bits (drastic) | E7: 1 | F7: =Recall!Q35 -> 0.2 | G7: =Recall!Q36 -> 0.2 | H7: =Recall!Q37 -> 0.2 | I7: =Recall!Q38 -> 0.2 | J7: =Recall!Q39 -> 0.19 | K7: =Recall!Q40 -> 0.195 | L7: =Recall!Q41 -> 0.19 | M7: =Recall!Q42 -> 0.2 | N7: =Recall!Q43 -> 0.19 | O7: =Recall!Q44 -> 0.235 | P7: =Recall!Q45 -> 0.2
A8: C05 | B8: FP32 | C8: late | D8: Exponent, low bits | E8: 16 | F8: =Recall!Q46 -> 0 | G8: =Recall!Q47 -> 0.05 | H8: =Recall!Q48 -> 0.005 | I8: =Recall!Q49 -> 0.03 | J8: =Recall!Q50 -> 0.005 | K8: =Recall!Q51 -> 0.015 | L8: =Recall!Q52 -> 0.01 | M8: =Recall!Q53 -> 0 | N8: =Recall!Q54 -> 0.005 | O8: =Recall!Q55 -> 0.05 | P8: =Recall!Q56 -> 0.017
A9: C06 | B9: FP32 | C9: middle | D9: Mantissa, high bits | E9: 16 | F9: =Recall!Q57 -> 0 | G9: =Recall!Q58 -> 0 | H9: =Recall!Q59 -> 0 | I9: =Recall!Q60 -> 0 | J9: =Recall!Q61 -> 0 | K9: =Recall!Q62 -> 0 | L9: =Recall!Q63 -> 0 | M9: =Recall!Q64 -> 0 | N9: =Recall!Q65 -> 0 | O9: =Recall!Q66 -> 0.05 | P9: =Recall!Q67 -> 0.005
A10: C07 | B10: FP32 | C10: late | D10: Mantissa, low bits (subtle) | E10: 16 | F10: =Recall!Q68 -> 0 | G10: =Recall!Q69 -> 0 | H10: =Recall!Q70 -> 0 | I10: =Recall!Q71 -> 0 | J10: =Recall!Q72 -> 0 | K10: =Recall!Q73 -> 0 | L10: =Recall!Q74 -> 0 | M10: =Recall!Q75 -> 0 | N10: =Recall!Q76 -> 0 | O10: =Recall!Q77 -> 0.05 | P10: =Recall!Q78 -> 0.005
A11: C08 | B11: INT8 | C11: early | D11: Sign bit | E11: 4 | F11: =Recall!Q79 -> 0 | G11: =Recall!Q80 -> 0 | H11: =Recall!Q81 -> 0.005 | I11: =Recall!Q82 -> 0 | J11: =Recall!Q83 -> 0 | K11: =Recall!Q84 -> 0.005 | L11: =Recall!Q85 -> 0.005 | M11: =Recall!Q86 -> 0 | N11: =Recall!Q87 -> 0 | O11: =Recall!Q88 -> 0.04 | P11: =Recall!Q89 -> 0.0055
A12: C09 | B12: INT8 | C12: late | D12: Top magnitude bit | E12: 16 | F12: =Recall!Q90 -> 0 | G12: =Recall!Q91 -> 0 | H12: =Recall!Q92 -> 0 | I12: =Recall!Q93 -> 0.01 | J12: =Recall!Q94 -> 0.005 | K12: =Recall!Q95 -> 0 | L12: =Recall!Q96 -> 0 | M12: =Recall!Q97 -> 0.005 | N12: =Recall!Q98 -> 0 | O12: =Recall!Q99 -> 0.05 | P12: =Recall!Q100 -> 0.007
A13: C10 | B13: FP16 | C13: early | D13: Sign bit | E13: 16 | F13: =Recall!Q101 -> 0 | G13: =Recall!Q102 -> 0 | H13: =Recall!Q103 -> 0 | I13: =Recall!Q104 -> 0 | J13: =Recall!Q105 -> 0 | K13: =Recall!Q106 -> 0 | L13: =Recall!Q107 -> 0.01 | M13: =Recall!Q108 -> 0 | N13: =Recall!Q109 -> 0 | O13: =Recall!Q110 -> 0.045 | P13: =Recall!Q111 -> 0.0055
A15: Each class has 20 pictures per run, so one picture is 5 points. The truck class contains one picture the monitor flags even on the healthy model.

Sheet Configurations
A1: Config | B1: Weight format | C1: Where | D1: Which bit | E1: Bits | F1: Flips per run | G1: Repetitions | H1: Pictures per run
A2: C01 | B2: FP32 | C2: Early layers (stem, stage 1) | D2: Sign bit | E2: 31 | F2: 16 | G2: 10 | H2: 200
A3: C02 | B3: FP32 | C3: Early layers (stem, stage 1) | D3: Exponent, top bits (drastic) | E3: 30–27 | F3: 1 | G3: 10 | H3: 200
A4: C03 | B4: FP32 | C4: Middle layers (stage 2) | D4: Exponent, top bits (drastic) | E4: 30–27 | F4: 4 | G4: 10 | H4: 200
A5: C04 | B5: FP32 | C5: Late layers (stage 3, fc) | D5: Exponent, top bits (drastic) | E5: 30–27 | F5: 1 | G5: 10 | H5: 200
A6: C05 | B6: FP32 | C6: Late layers (stage 3, fc) | D6: Exponent, low bits | E6: 26–23 | F6: 16 | G6: 10 | H6: 200
A7: C06 | B7: FP32 | C7: Middle layers (stage 2) | D7: Mantissa, high bits | E7: 22–16 | F7: 16 | G7: 10 | H7: 200
A8: C07 | B8: FP32 | C8: Late layers (stage 3, fc) | D8: Mantissa, low bits (subtle) | E8: 15–0 | F8: 16 | G8: 10 | H8: 200
A9: C08 | B9: INT8 | C9: Early layers (stem, stage 1) | D9: Sign bit | E9: 7 | F9: 4 | G9: 10 | H9: 200
A10: C09 | B10: INT8 | C10: Late layers (stage 3, fc) | D10: Top magnitude bit | E10: 6 | F10: 16 | G10: 10 | H10: 200
A11: C10 | B11: FP16 | C11: Early layers (stem, stage 1) | D11: Sign bit | E11: 15 | F11: 16 | G11: 10 | H11: 200
A13: Blue = chosen inputs. Bits: positions in the format's code (FP32 bit 31 = sign; INT8 bit 7 = sign).

Sheet Runs
A1: Config | B1: Format | C1: Where | D1: Which bit | E1: Flips | F1: Repetition | G1: Class | H1: α (allowed false alarms) | I1: Pictures | J1: TP | K1: FN | L1: FP | M1: TN | N1: Recall | O1: Precision | P1: F1 | Q1: False-alarm rate | R1: Answers changed | S1: Recall: answer changed | T1: Recall: answer unchanged | U1: Accuracy before | V1: Accuracy after
A2: C01 | B2: FP32 | C2: early | D2: sign | E2: 16 | F2: 1 | G2: airplane | H2: 0.05 | I2: 20 | J2: 2 | K2: 18 | L2: 2 | M2: 18 | N2: =J2/(J2+K2) -> 0.1 | O2: =IF(J2+L2=0,"",J2/(J2+L2)) -> 0.5 | P2: =2*J2/(2*J2+L2+K2) -> 0.16666667 | Q2: =L2/(L2+M2) -> 0.1 | R2: 2 | S2: 0 | T2: 0.11111111 | U2: 0.85 | V2: 0.8
A3: C01 | B3: FP32 | C3: early | D3: sign | E3: 16 | F3: 1 | G3: automobile | H3: 0.05 | I3: 20 | J3: 2 | K3: 18 | L3: 1 | M3: 19 | N3: =J3/(J3+K3) -> 0.1 | O3: =IF(J3+L3=0,"",J3/(J3+L3)) -> 0.66666667 | P3: =2*J3/(2*J3+L3+K3) -> 0.17391304 | Q3: =L3/(L3+M3) -> 0.05 | R3: 0 | T3: 0.1 | U3: 1 | V3: 1
A4: C01 | B4: FP32 | C4: early | D4: sign | E4: 16 | F4: 1 | G4: bird | H4: 0.05 | I4: 20 | J4: 0 | K4: 20 | L4: 0 | M4: 20 | N4: =J4/(J4+K4) -> 0 | O4: =IF(J4+L4=0,"",J4/(J4+L4)) | P4: =2*J4/(2*J4+L4+K4) -> 0 | Q4: =L4/(L4+M4) -> 0 | R4: 2 | S4: 0 | T4: 0 | U4: 0.9 | V4: 1
A5: C01 | B5: FP32 | C5: early | D5: sign | E5: 16 | F5: 1 | G5: cat | H5: 0.05 | I5: 20 | J5: 0 | K5: 20 | L5: 0 | M5: 20 | N5: =J5/(J5+K5) -> 0 | O5: =IF(J5+L5=0,"",J5/(J5+L5)) | P5: =2*J5/(2*J5+L5+K5) -> 0 | Q5: =L5/(L5+M5) -> 0 | R5: 1 | S5: 0 | T5: 0 | U5: 0.8 | V5: 0.75
A6: C01 | B6: FP32 | C6: early | D6: sign | E6: 16 | F6: 1 | G6: deer | H6: 0.05 | I6: 20 | J6: 0 | K6: 20 | L6: 1 | M6: 19 | N6: =J6/(J6+K6) -> 0 | O6: =IF(J6+L6=0,"",J6/(J6+L6)) -> 0 | P6: =2*J6/(2*J6+L6+K6) -> 0 | Q6: =L6/(L6+M6) -> 0.05 | R6: 1 | S6: 0 | T6: 0 | U6: 0.9 | V6: 0.85
A7: C01 | B7: FP32 | C7: early | D7: sign | E7: 16 | F7: 1 | G7: dog | H7: 0.05 | I7: 20 | J7: 0 | K7: 20 | L7: 0 | M7: 20 | N7: =J7/(J7+K7) -> 0 | O7: =IF(J7+L7=0,"",J7/(J7+L7)) | P7: =2*J7/(2*J7+L7+K7) -> 0 | Q7: =L7/(L7+M7) -> 0 | R7: 1 | S7: 0 | T7: 0 | U7: 0.65 | V7: 0.65
A8: C01 | B8: FP32 | C8: early | D8: sign | E8: 16 | F8: 1 | G8: frog | H8: 0.05 | I8: 20 | J8: 1 | K8: 19 | L8: 1 | M8: 19 | N8: =J8/(J8+K8) -> 0.05 | O8: =IF(J8+L8=0,"",J8/(J8+L8)) -> 0.5 | P8: =2*J8/(2*J8+L8+K8) -> 0.090909091 | Q8: =L8/(L8+M8) -> 0.05 | R8: 4 | S8: 0.25 | T8: 0 | U8: 0.85 | V8: 0.8
A9: C01 | B9: FP32 | C9: early | D9: sign | E9: 16 | F9: 1 | G9: horse | H9: 0.05 | I9: 20 | J9: 0 | K9: 20 | L9: 0 | M9: 20 | N9: =J9/(J9+K9) -> 0 | O9: =IF(J9+L9=0,"",J9/(J9+L9)) | P9: =2*J9/(2*J9+L9+K9) -> 0 | Q9: =L9/(L9+M9) -> 0 | R9: 2 | S9: 0 | T9: 0 | U9: 0.9 | V9: 0.9
A10: C01 | B10: FP32 | C10: early | D10: sign | E10: 16 | F10: 1 | G10: ship | H10: 0.05 | I10: 20 | J10: 0 | K10: 20 | L10: 0 | M10: 20 | N10: =J10/(J10+K10) -> 0 | O10: =IF(J10+L10=0,"",J10/(J10+L10)) | P10: =2*J10/(2*J10+L10+K10) -> 0 | Q10: =L10/(L10+M10) -> 0 | R10: 0 | T10: 0 | U10: 0.95 | V10: 0.95
A11: C01 | B11: FP32 | C11: early | D11: sign | E11: 16 | F11: 1 | G11: truck | H11: 0.05 | I11: 20 | J11: 0 | K11: 20 | L11: 1 | M11: 19 | N11: =J11/(J11+K11) -> 0 | O11: =IF(J11+L11=0,"",J11/(J11+L11)) -> 0 | P11: =2*J11/(2*J11+L11+K11) -> 0 | Q11: =L11/(L11+M11) -> 0.05 | R11: 0 | T11: 0 | U11: 1 | V11: 1
A12: C01 | B12: FP32 | C12: early | D12: sign | E12: 16 | F12: 1 | G12: ALL | H12: 0.05 | I12: 200 | J12: 5 | K12: 195 | L12: 6 | M12: 194 | N12: =J12/(J12+K12) -> 0.025 | O12: =IF(J12+L12=0,"",J12/(J12+L12)) -> 0.45454545 | P12: =2*J12/(2*J12+L12+K12) -> 0.047393365 | Q12: =L12/(L12+M12) -> 0.03 | R12: 13 | S12: 0.076923077 | T12: 0.021390374 | U12: 0.88 | V12: 0.87
A13: C01 | B13: FP32 | C13: early | D13: sign | E13: 16 | F13: 2 | G13: airplane | H13: 0.05 | I13: 20 | J13: 1 | K13: 19 | L13: 2 | M13: 18 | N13: =J13/(J13+K13) -> 0.05 | O13: =IF(J13+L13=0,"",J13/(J13+L13)) -> 0.33333333 | P13: =2*J13/(2*J13+L13+K13) -> 0.086956522 | Q13: =L13/(L13+M13) -> 0.1 | R13: 0 | T13: 0.05 | U13: 0.85 | V13: 0.85
A14: C01 | B14: FP32 | C14: early | D14: sign | E14: 16 | F14: 2 | G14: automobile | H14: 0.05 | I14: 20 | J14: 1 | K14: 19 | L14: 1 | M14: 19 | N14: =J14/(J14+K14) -> 0.05 | O14: =IF(J14+L14=0,"",J14/(J14+L14)) -> 0.5 | P14: =2*J14/(2*J14+L14+K14) -> 0.090909091 | Q14: =L14/(L14+M14) -> 0.05 | R14: 0 | T14: 0.05 | U14: 1 | V14: 1
A15: C01 | B15: FP32 | C15: early | D15: sign | E15: 16 | F15: 2 | G15: bird | H15: 0.05 | I15: 20 | J15: 0 | K15: 20 | L15: 0 | M15: 20 | N15: =J15/(J15+K15) -> 0 | O15: =IF(J15+L15=0,"",J15/(J15+L15)) | P15: =2*J15/(2*J15+L15+K15) -> 0 | Q15: =L15/(L15+M15) -> 0 | R15: 0 | T15: 0 | U15: 0.9 | V15: 0.9
A16: C01 | B16: FP32 | C16: early | D16: sign | E16: 16 | F16: 2 | G16: cat | H16: 0.05 | I16: 20 | J16: 0 | K16: 20 | L16: 0 | M16: 20 | N16: =J16/(J16+K16) -> 0 | O16: =IF(J16+L16=0,"",J16/(J16+L16)) | P16: =2*J16/(2*J16+L16+K16) -> 0 | Q16: =L16/(L16+M16) -> 0 | R16: 0 | T16: 0 | U16: 0.8 | V16: 0.8
A17: C01 | B17: FP32 | C17: early | D17: sign | E17: 16 | F17: 2 | G17: deer | H17: 0.05 | I17: 20 | J17: 0 | K17: 20 | L17: 1 | M17: 19 | N17: =J17/(J17+K17) -> 0 | O17: =IF(J17+L17=0,"",J17/(J17+L17)) -> 0 | P17: =2*J17/(2*J17+L17+K17) -> 0 | Q17: =L17/(L17+M17) -> 0.05 | R17: 0 | T17: 0 | U17: 0.9 | V17: 0.9
A18: C01 | B18: FP32 | C18: early | D18: sign | E18: 16 | F18: 2 | G18: dog | H18: 0.05 | I18: 20 | J18: 0 | K18: 20 | L18: 0 | M18: 20 | N18: =J18/(J18+K18) -> 0 | O18: =IF(J18+L18=0,"",J18/(J18+L18)) | P18: =2*J18/(2*J18+L18+K18) -> 0 | Q18: =L18/(L18+M18) -> 0 | R18: 1 | S18: 0 | T18: 0 | U18: 0.65 | V18: 0.65
A19: C01 | B19: FP32 | C19: early | D19: sign | E19: 16 | F19: 2 | G19: frog | H19: 0.05 | I19: 20 | J19: 1 | K19: 19 | L19: 1 | M19: 19 | N19: =J19/(J19+K19) -> 0.05 | O19: =IF(J19+L19=0,"",J19/(J19+L19)) -> 0.5 | P19: =2*J19/(2*J19+L19+K19) -> 0.090909091 | Q19: =L19/(L19+M19) -> 0.05 | R19: 1 | S19: 0 | T19: 0.052631579 | U19: 0.85 | V19: 0.9
A20: C01 | B20: FP32 | C20: early | D20: sign | E20: 16 | F20: 2 | G20: horse | H20: 0.05 | I20: 20 | J20: 0 | K20: 20 | L20: 0 | M20: 20 | N20: =J20/(J20+K20) -> 0 | O20: =IF(J20+L20=0,"",J20/(J20+L20)) | P20: =2*J20/(2*J20+L20+K20) -> 0 | Q20: =L20/(L20+M20) -> 0 | R20: 0 | T20: 0 | U20: 0.9 | V20: 0.9
A21: C01 | B21: FP32 | C21: early | D21: sign | E21: 16 | F21: 2 | G21: ship | H21: 0.05 | I21: 20 | J21: 0 | K21: 20 | L21: 0 | M21: 20 | N21: =J21/(J21+K21) -> 0 | O21: =IF(J21+L21=0,"",J21/(J21+L21)) | P21: =2*J21/(2*J21+L21+K21) -> 0 | Q21: =L21/(L21+M21) -> 0 | R21: 0 | T21: 0 | U21: 0.95 | V21: 0.95
A22: C01 | B22: FP32 | C22: early | D22: sign | E22: 16 | F22: 2 | G22: truck | H22: 0.05 | I22: 20 | J22: 1 | K22: 19 | L22: 1 | M22: 19 | N22: =J22/(J22+K22) -> 0.05 | O22: =IF(J22+L22=0,"",J22/(J22+L22)) -> 0.5 | P22: =2*J22/(2*J22+L22+K22) -> 0.090909091 | Q22: =L22/(L22+M22) -> 0.05 | R22: 0 | T22: 0.05 | U22: 1 | V22: 1
A23: C01 | B23: FP32 | C23: early | D23: sign | E23: 16 | F23: 2 | G23: ALL | H23: 0.05 | I23: 200 | J23: 4 | K23: 196 | L23: 6 | M23: 194 | N23: =J23/(J23+K23) -> 0.02 | O23: =IF(J23+L23=0,"",J23/(J23+L23)) -> 0.4 | P23: =2*J23/(2*J23+L23+K23) -> 0.038095238 | Q23: =L23/(L23+M23) -> 0.03 | R23: 2 | S23: 0 | T23: 0.02020202 | U23: 0.88 | V23: 0.885
A24: C01 | B24: FP32 | C24: early | D24: sign | E24: 16 | F24: 3 | G24: airplane | H24: 0.05 | I24: 20 | J24: 2 | K24: 18 | L24: 2 | M24: 18 | N24: =J24/(J24+K24) -> 0.1 | O24: =IF(J24+L24=0,"",J24/(J24+L24)) -> 0.5 | P24: =2*J24/(2*J24+L24+K24) -> 0.16666667 | Q24: =L24/(L24+M24) -> 0.1 | R24: 1 | S24: 0 | T24: 0.10526316 | U24: 0.85 | V24: 0.85
A25: C01 | B25: FP32 | C25: early | D25: sign | E25: 16 | F25: 3 | G25: automobile | H25: 0.05 | I25: 20 | J25: 1 | K25: 19 | L25: 1 | M25: 19 | N25: =J25/(J25+K25) -> 0.05 | O25: =IF(J25+L25=0,"",J25/(J25+L25)) -> 0.5 | P25: =2*J25/(2*J25+L25+K25) -> 0.090909091 | Q25: =L25/(L25+M25) -> 0.05 | R25: 0 | T25: 0.05 | U25: 1 | V25: 1
A26: C01 | B26: FP32 | C26: early | D26: sign | E26: 16 | F26: 3 | G26: bird | H26: 0.05 | I26: 20 | J26: 0 | K26: 20 | L26: 0 | M26: 20 | N26: =J26/(J26+K26) -> 0 | O26: =IF(J26+L26=0,"",J26/(J26+L26)) | P26: =2*J26/(2*J26+L26+K26) -> 0 | Q26: =L26/(L26+M26) -> 0 | R26: 0 | T26: 0 | U26: 0.9 | V26: 0.9
A27: C01 | B27: FP32 | C27: early | D27: sign | E27: 16 | F27: 3 | G27: cat | H27: 0.05 | I27: 20 | J27: 0 | K27: 20 | L27: 0 | M27: 20 | N27: =J27/(J27+K27) -> 0 | O27: =IF(J27+L27=0,"",J27/(J27+L27)) | P27: =2*J27/(2*J27+L27+K27) -> 0 | Q27: =L27/(L27+M27) -> 0 | R27: 0 | T27: 0 | U27: 0.8 | V27: 0.8
A28: C01 | B28: FP32 | C28: early | D28: sign | E28: 16 | F28: 3 | G28: deer | H28: 0.05 | I28: 20 | J28: 1 | K28: 19 | L28: 1 | M28: 19 | N28: =J28/(J28+K28) -> 0.05 | O28: =IF(J28+L28=0,"",J28/(J28+L28)) -> 0.5 | P28: =2*J28/(2*J28+L28+K28) -> 0.090909091 | Q28: =L28/(L28+M28) -> 0.05 | R28: 0 | T28: 0.05 | U28: 0.9 | V28: 0.9
A29: C01 | B29: FP32 | C29: early | D29: sign | E29: 16 | F29: 3 | G29: dog | H29: 0.05 | I29: 20 | J29: 0 | K29: 20 | L29: 0 | M29: 20 | N29: =J29/(J29+K29) -> 0 | O29: =IF(J29+L29=0,"",J29/(J29+L29)) | P29: =2*J29/(2*J29+L29+K29) -> 0 | Q29: =L29/(L29+M29) -> 0 | R29: 0 | T29: 0 | U29: 0.65 | V29: 0.65
A30: C01 | B30: FP32 | C30: early | D30: sign | E30: 16 | F30: 3 | G30: frog | H30: 0.05 | I30: 20 | J30: 1 | K30: 19 | L30: 1 | M30: 19 | N30: =J30/(J30+K30) -> 0.05 | O30: =IF(J30+L30=0,"",J30/(J30+L30)) -> 0.5 | P30: =2*J30/(2*J30+L30+K30) -> 0.090909091 | Q30: =L30/(L30+M30) -> 0.05 | R30: 2 | S30: 0 | T30: 0.055555556 | U30: 0.85 | V30: 0.9
A31: C01 | B31: FP32 | C31: early | D31: sign | E31: 16 | F31: 3 | G31: horse | H31: 0.05 | I31: 20 | J31: 0 | K31: 20 | L31: 0 | M31: 20 | N31: =J31/(J31+K31) -> 0 | O31: =IF(J31+L31=0,"",J31/(J31+L31)) | P31: =2*J31/(2*J31+L31+K31) -> 0 | Q31: =L31/(L31+M31) -> 0 | R31: 1 | S31: 0 | T31: 0 | U31: 0.9 | V31: 0.95
A32: C01 | B32: FP32 | C32: early | D32: sign | E32: 16 | F32: 3 | G32: ship | H32: 0.05 | I32: 20 | J32: 0 | K32: 20 | L32: 0 | M32: 20 | N32: =J32/(J32+K32) -> 0 | O32: =IF(J32+L32=0,"",J32/(J32+L32)) | P32: =2*J32/(2*J32+L32+K32) -> 0 | Q32: =L32/(L32+M32) -> 0 | R32: 0 | T32: 0 | U32: 0.95 | V32: 0.95
A33: C01 | B33: FP32 | C33: early | D33: sign | E33: 16 | F33: 3 | G33: truck | H33: 0.05 | I33: 20 | J33: 1 | K33: 19 | L33: 1 | M33: 19 | N33: =J33/(J33+K33) -> 0.05 | O33: =IF(J33+L33=0,"",J33/(J33+L33)) -> 0.5 | P33: =2*J33/(2*J33+L33+K33) -> 0.090909091 | Q33: =L33/(L33+M33) -> 0.05 | R33: 0 | T33: 0.05 | U33: 1 | V33: 1
A34: C01 | B34: FP32 | C34: early | D34: sign | E34: 16 | F34: 3 | G34: ALL | H34: 0.05 | I34: 200 | J34: 6 | K34: 194 | L34: 6 | M34: 194 | N34: =J34/(J34+K34) -> 0.03 | O34: =IF(J34+L34=0,"",J34/(J34+L34)) -> 0.5 | P34: =2*J34/(2*J34+L34+K34) -> 0.056603774 | Q34: =L34/(L34+M34) -> 0.03 | R34: 4 | S34: 0 | T34: 0.030612245 | U34: 0.88 | V34: 0.89
A35: C01 | B35: FP32 | C35: early | D35: sign | E35: 16 | F35: 4 | G35: airplane | H35: 0.05 | I35: 20 | J35: 2 | K35: 18 | L35: 2 | M35: 18 | N35: =J35/(J35+K35) -> 0.1 | O35: =IF(J35+L35=0,"",J35/(J35+L35)) -> 0.5 | P35: =2*J35/(2*J35+L35+K35) -> 0.16666667 | Q35: =L35/(L35+M35) -> 0.1 | R35: 0 | T35: 0.1 | U35: 0.85 | V35: 0.85
A36: C01 | B36: FP32 | C36: early | D36: sign | E36: 16 | F36: 4 | G36: automobile | H36: 0.05 | I36: 20 | J36: 1 | K36: 19 | L36: 1 | M36: 19 | N36: =J36/(J36+K36) -> 0.05 | O36: =IF(J36+L36=0,"",J36/(J36+L36)) -> 0.5 | P36: =2*J36/(2*J36+L36+K36) -> 0.090909091 | Q36: =L36/(L36+M36) -> 0.05 | R36: 0 | T36: 0.05 | U36: 1 | V36: 1
A37: C01 | B37: FP32 | C37: early | D37: sign | E37: 16 | F37: 4 | G37: bird | H37: 0.05 | I37: 20 | J37: 0 | K37: 20 | L37: 0 | M37: 20 | N37: =J37/(J37+K37) -> 0 | O37: =IF(J37+L37=0,"",J37/(J37+L37)) | P37: =2*J37/(2*J37+L37+K37) -> 0 | Q37: =L37/(L37+M37) -> 0 | R37: 0 | T37: 0 | U37: 0.9 | V37: 0.9
A38: C01 | B38: FP32 | C38: early | D38: sign | E38: 16 | F38: 4 | G38: cat | H38: 0.05 | I38: 20 | J38: 0 | K38: 20 | L38: 0 | M38: 20 | N38: =J38/(J38+K38) -> 0 | O38: =IF(J38+L38=0,"",J38/(J38+L38)) | P38: =2*J38/(2*J38+L38+K38) -> 0 | Q38: =L38/(L38+M38) -> 0 | R38: 0 | T38: 0 | U38: 0.8 | V38: 0.8
A39: C01 | B39: FP32 | C39: early | D39: sign | E39: 16 | F39: 4 | G39: deer | H39: 0.05 | I39: 20 | J39: 1 | K39: 19 | L39: 1 | M39: 19 | N39: =J39/(J39+K39) -> 0.05 | O39: =IF(J39+L39=0,"",J39/(J39+L39)) -> 0.5 | P39: =2*J39/(2*J39+L39+K39) -> 0.090909091 | Q39: =L39/(L39+M39) -> 0.05 | R39: 0 | T39: 0.05 | U39: 0.9 | V39: 0.9
A40: C01 | B40: FP32 | C40: early | D40: sign | E40: 16 | F40: 4 | G40: dog | H40: 0.05 | I40: 20 | J40: 0 | K40: 20 | L40: 0 | M40: 20 | N40: =J40/(J40+K40) -> 0 | O40: =IF(J40+L40=0,"",J40/(J40+L40)) | P40: =2*J40/(2*J40+L40+K40) -> 0 | Q40: =L40/(L40+M40) -> 0 | R40: 2 | S40: 0 | T40: 0 | U40: 0.65 | V40: 0.65
...

Sheet Recall
A1: Config | B1: Format | C1: Where | D1: Which bit | E1: Flips | F1: Class | G1: Rep 1 | H1: Rep 2 | I1: Rep 3 | J1: Rep 4 | K1: Rep 5 | L1: Rep 6 | M1: Rep 7 | N1: Rep 8 | O1: Rep 9 | P1: Rep 10 | Q1: Mean | R1: SD | S1: N
A2: C01 | B2: FP32 | C2: early | D2: sign | E2: 16 | F2: airplane | G2: =Runs!N1102 -> 0 | H2: =Runs!N1113 -> 0 | I2: =Runs!N1124 -> 0 | J2: =Runs!N1135 -> 0 | K2: =Runs!N1146 -> 0 | L2: =Runs!N1157 -> 0 | M2: =Runs!N1168 -> 0 | N2: =Runs!N1179 -> 0 | O2: =Runs!N1190 -> 0 | P2: =Runs!N1201 -> 0 | Q2: =IF(COUNT(G2:P2)=0,"",AVERAGE(G2:P2)) -> 0 | R2: =IF(COUNT(G2:P2)<2,"",STDEV(G2:P2)) -> 0 | S2: =COUNT(G2:P2) -> 10
A3: C01 | B3: FP32 | C3: early | D3: sign | E3: 16 | F3: automobile | G3: =Runs!N1103 -> 0.05 | H3: =Runs!N1114 -> 0 | I3: =Runs!N1125 -> 0 | J3: =Runs!N1136 -> 0 | K3: =Runs!N1147 -> 0 | L3: =Runs!N1158 -> 0 | M3: =Runs!N1169 -> 0 | N3: =Runs!N1180 -> 0 | O3: =Runs!N1191 -> 0 | P3: =Runs!N1202 -> 0 | Q3: =IF(COUNT(G3:P3)=0,"",AVERAGE(G3:P3)) -> 0.005 | R3: =IF(COUNT(G3:P3)<2,"",STDEV(G3:P3)) -> 0.015811388 | S3: =COUNT(G3:P3) -> 10
A4: C01 | B4: FP32 | C4: early | D4: sign | E4: 16 | F4: bird | G4: =Runs!N1104 -> 0 | H4: =Runs!N1115 -> 0 | I4: =Runs!N1126 -> 0 | J4: =Runs!N1137 -> 0 | K4: =Runs!N1148 -> 0 | L4: =Runs!N1159 -> 0 | M4: =Runs!N1170 -> 0 | N4: =Runs!N1181 -> 0 | O4: =Runs!N1192 -> 0 | P4: =Runs!N1203 -> 0 | Q4: =IF(COUNT(G4:P4)=0,"",AVERAGE(G4:P4)) -> 0 | R4: =IF(COUNT(G4:P4)<2,"",STDEV(G4:P4)) -> 0 | S4: =COUNT(G4:P4) -> 10
A5: C01 | B5: FP32 | C5: early | D5: sign | E5: 16 | F5: cat | G5: =Runs!N1105 -> 0 | H5: =Runs!N1116 -> 0 | I5: =Runs!N1127 -> 0 | J5: =Runs!N1138 -> 0 | K5: =Runs!N1149 -> 0 | L5: =Runs!N1160 -> 0 | M5: =Runs!N1171 -> 0 | N5: =Runs!N1182 -> 0 | O5: =Runs!N1193 -> 0 | P5: =Runs!N1204 -> 0 | Q5: =IF(COUNT(G5:P5)=0,"",AVERAGE(G5:P5)) -> 0 | R5: =IF(COUNT(G5:P5)<2,"",STDEV(G5:P5)) -> 0 | S5: =COUNT(G5:P5) -> 10
A6: C01 | B6: FP32 | C6: early | D6: sign | E6: 16 | F6: deer | G6: =Runs!N1106 -> 0 | H6: =Runs!N1117 -> 0 | I6: =Runs!N1128 -> 0 | J6: =Runs!N1139 -> 0 | K6: =Runs!N1150 -> 0 | L6: =Runs!N1161 -> 0 | M6: =Runs!N1172 -> 0 | N6: =Runs!N1183 -> 0 | O6: =Runs!N1194 -> 0 | P6: =Runs!N1205 -> 0 | Q6: =IF(COUNT(G6:P6)=0,"",AVERAGE(G6:P6)) -> 0 | R6: =IF(COUNT(G6:P6)<2,"",STDEV(G6:P6)) -> 0 | S6: =COUNT(G6:P6) -> 10
A7: C01 | B7: FP32 | C7: early | D7: sign | E7: 16 | F7: dog | G7: =Runs!N1107 -> 0 | H7: =Runs!N1118 -> 0 | I7: =Runs!N1129 -> 0 | J7: =Runs!N1140 -> 0 | K7: =Runs!N1151 -> 0 | L7: =Runs!N1162 -> 0 | M7: =Runs!N1173 -> 0 | N7: =Runs!N1184 -> 0 | O7: =Runs!N1195 -> 0 | P7: =Runs!N1206 -> 0 | Q7: =IF(COUNT(G7:P7)=0,"",AVERAGE(G7:P7)) -> 0 | R7: =IF(COUNT(G7:P7)<2,"",STDEV(G7:P7)) -> 0 | S7: =COUNT(G7:P7) -> 10
A8: C01 | B8: FP32 | C8: early | D8: sign | E8: 16 | F8: frog | G8: =Runs!N1108 -> 0 | H8: =Runs!N1119 -> 0 | I8: =Runs!N1130 -> 0 | J8: =Runs!N1141 -> 0 | K8: =Runs!N1152 -> 0.05 | L8: =Runs!N1163 -> 0 | M8: =Runs!N1174 -> 0 | N8: =Runs!N1185 -> 0.05 | O8: =Runs!N1196 -> 0.05 | P8: =Runs!N1207 -> 0 | Q8: =IF(COUNT(G8:P8)=0,"",AVERAGE(G8:P8)) -> 0.015 | R8: =IF(COUNT(G8:P8)<2,"",STDEV(G8:P8)) -> 0.024152295 | S8: =COUNT(G8:P8) -> 10
A9: C01 | B9: FP32 | C9: early | D9: sign | E9: 16 | F9: horse | G9: =Runs!N1109 -> 0 | H9: =Runs!N1120 -> 0 | I9: =Runs!N1131 -> 0 | J9: =Runs!N1142 -> 0 | K9: =Runs!N1153 -> 0 | L9: =Runs!N1164 -> 0 | M9: =Runs!N1175 -> 0 | N9: =Runs!N1186 -> 0 | O9: =Runs!N1197 -> 0 | P9: =Runs!N1208 -> 0 | Q9: =IF(COUNT(G9:P9)=0,"",AVERAGE(G9:P9)) -> 0 | R9: =IF(COUNT(G9:P9)<2,"",STDEV(G9:P9)) -> 0 | S9: =COUNT(G9:P9) -> 10
A10: C01 | B10: FP32 | C10: early | D10: sign | E10: 16 | F10: ship | G10: =Runs!N1110 -> 0 | H10: =Runs!N1121 -> 0 | I10: =Runs!N1132 -> 0 | J10: =Runs!N1143 -> 0 | K10: =Runs!N1154 -> 0 | L10: =Runs!N1165 -> 0 | M10: =Runs!N1176 -> 0 | N10: =Runs!N1187 -> 0 | O10: =Runs!N1198 -> 0 | P10: =Runs!N1209 -> 0 | Q10: =IF(COUNT(G10:P10)=0,"",AVERAGE(G10:P10)) -> 0 | R10: =IF(COUNT(G10:P10)<2,"",STDEV(G10:P10)) -> 0 | S10: =COUNT(G10:P10) -> 10
A11: C01 | B11: FP32 | C11: early | D11: sign | E11: 16 | F11: truck | G11: =Runs!N1111 -> 0 | H11: =Runs!N1122 -> 0.05 | I11: =Runs!N1133 -> 0.05 | J11: =Runs!N1144 -> 0.05 | K11: =Runs!N1155 -> 0.05 | L11: =Runs!N1166 -> 0 | M11: =Runs!N1177 -> 0.05 | N11: =Runs!N1188 -> 0 | O11: =Runs!N1199 -> 0.05 | P11: =Runs!N1210 -> 0.05 | Q11: =IF(COUNT(G11:P11)=0,"",AVERAGE(G11:P11)) -> 0.035 | R11: =IF(COUNT(G11:P11)<2,"",STDEV(G11:P11)) -> 0.024152295 | S11: =COUNT(G11:P11) -> 10
A12: C01 | B12: FP32 | C12: early | D12: sign | E12: 16 | F12: ALL | G12: =Runs!N1112 -> 0.005 | H12: =Runs!N1123 -> 0.005 | I12: =Runs!N1134 -> 0.005 | J12: =Runs!N1145 -> 0.005 | K12: =Runs!N1156 -> 0.01 | L12: =Runs!N1167 -> 0 | M12: =Runs!N1178 -> 0.005 | N12: =Runs!N1189 -> 0.005 | O12: =Runs!N1200 -> 0.01 | P12: =Runs!N1211 -> 0.005 | Q12: =IF(COUNT(G12:P12)=0,"",AVERAGE(G12:P12)) -> 0.0055 | R12: =IF(COUNT(G12:P12)<2,"",STDEV(G12:P12)) -> 0.0028382311 | S12: =COUNT(G12:P12) -> 10
A13: C02 | B13: FP32 | C13: early | D13: exp_msb | E13: 1 | F13: airplane | G13: =Runs!N1212 -> 0 | H13: =Runs!N1223 -> 0 | I13: =Runs!N1234 -> 0 | J13: =Runs!N1245 -> 1 | K13: =Runs!N1256 -> 0 | L13: =Runs!N1267 -> 1 | M13: =Runs!N1278 -> 0 | N13: =Runs!N1289 -> 0 | O13: =Runs!N1300 -> 0 | P13: =Runs!N1311 -> 0 | Q13: =IF(COUNT(G13:P13)=0,"",AVERAGE(G13:P13)) -> 0.2 | R13: =IF(COUNT(G13:P13)<2,"",STDEV(G13:P13)) -> 0.42163702 | S13: =COUNT(G13:P13) -> 10
A14: C02 | B14: FP32 | C14: early | D14: exp_msb | E14: 1 | F14: automobile | G14: =Runs!N1213 -> 0 | H14: =Runs!N1224 -> 0 | I14: =Runs!N1235 -> 0 | J14: =Runs!N1246 -> 1 | K14: =Runs!N1257 -> 0 | L14: =Runs!N1268 -> 1 | M14: =Runs!N1279 -> 0 | N14: =Runs!N1290 -> 0 | O14: =Runs!N1301 -> 0 | P14: =Runs!N1312 -> 0 | Q14: =IF(COUNT(G14:P14)=0,"",AVERAGE(G14:P14)) -> 0.2 | R14: =IF(COUNT(G14:P14)<2,"",STDEV(G14:P14)) -> 0.42163702 | S14: =COUNT(G14:P14) -> 10
A15: C02 | B15: FP32 | C15: early | D15: exp_msb | E15: 1 | F15: bird | G15: =Runs!N1214 -> 0 | H15: =Runs!N1225 -> 0 | I15: =Runs!N1236 -> 0 | J15: =Runs!N1247 -> 1 | K15: =Runs!N1258 -> 0 | L15: =Runs!N1269 -> 1 | M15: =Runs!N1280 -> 0 | N15: =Runs!N1291 -> 0 | O15: =Runs!N1302 -> 0 | P15: =Runs!N1313 -> 0 | Q15: =IF(COUNT(G15:P15)=0,"",AVERAGE(G15:P15)) -> 0.2 | R15: =IF(COUNT(G15:P15)<2,"",STDEV(G15:P15)) -> 0.42163702 | S15: =COUNT(G15:P15) -> 10
A16: C02 | B16: FP32 | C16: early | D16: exp_msb | E16: 1 | F16: cat | G16: =Runs!N1215 -> 0 | H16: =Runs!N1226 -> 0 | I16: =Runs!N1237 -> 0 | J16: =Runs!N1248 -> 1 | K16: =Runs!N1259 -> 0 | L16: =Runs!N1270 -> 1 | M16: =Runs!N1281 -> 0 | N16: =Runs!N1292 -> 0 | O16: =Runs!N1303 -> 0 | P16: =Runs!N1314 -> 0 | Q16: =IF(COUNT(G16:P16)=0,"",AVERAGE(G16:P16)) -> 0.2 | R16: =IF(COUNT(G16:P16)<2,"",STDEV(G16:P16)) -> 0.42163702 | S16: =COUNT(G16:P16) -> 10
A17: C02 | B17: FP32 | C17: early | D17: exp_msb | E17: 1 | F17: deer | G17: =Runs!N1216 -> 0 | H17: =Runs!N1227 -> 0 | I17: =Runs!N1238 -> 0 | J17: =Runs!N1249 -> 1 | K17: =Runs!N1260 -> 0 | L17: =Runs!N1271 -> 1 | M17: =Runs!N1282 -> 0 | N17: =Runs!N1293 -> 0 | O17: =Runs!N1304 -> 0 | P17: =Runs!N1315 -> 0 | Q17: =IF(COUNT(G17:P17)=0,"",AVERAGE(G17:P17)) -> 0.2 | R17: =IF(COUNT(G17:P17)<2,"",STDEV(G17:P17)) -> 0.42163702 | S17: =COUNT(G17:P17) -> 10
A18: C02 | B18: FP32 | C18: early | D18: exp_msb | E18: 1 | F18: dog | G18: =Runs!N1217 -> 0 | H18: =Runs!N1228 -> 0 | I18: =Runs!N1239 -> 0 | J18: =Runs!N1250 -> 1 | K18: =Runs!N1261 -> 0 | L18: =Runs!N1272 -> 1 | M18: =Runs!N1283 -> 0 | N18: =Runs!N1294 -> 0 | O18: =Runs!N1305 -> 0 | P18: =Runs!N1316 -> 0 | Q18: =IF(COUNT(G18:P18)=0,"",AVERAGE(G18:P18)) -> 0.2 | R18: =IF(COUNT(G18:P18)<2,"",STDEV(G18:P18)) -> 0.42163702 | S18: =COUNT(G18:P18) -> 10
A19: C02 | B19: FP32 | C19: early | D19: exp_msb | E19: 1 | F19: frog | G19: =Runs!N1218 -> 0 | H19: =Runs!N1229 -> 0 | I19: =Runs!N1240 -> 0 | J19: =Runs!N1251 -> 1 | K19: =Runs!N1262 -> 0 | L19: =Runs!N1273 -> 1 | M19: =Runs!N1284 -> 0 | N19: =Runs!N1295 -> 0 | O19: =Runs!N1306 -> 0 | P19: =Runs!N1317 -> 0 | Q19: =IF(COUNT(G19:P19)=0,"",AVERAGE(G19:P19)) -> 0.2 | R19: =IF(COUNT(G19:P19)<2,"",STDEV(G19:P19)) -> 0.42163702 | S19: =COUNT(G19:P19) -> 10
A20: C02 | B20: FP32 | C20: early | D20: exp_msb | E20: 1 | F20: horse | G20: =Runs!N1219 -> 0 | H20: =Runs!N1230 -> 0 | I20: =Runs!N1241 -> 0 | J20: =Runs!N1252 -> 1 | K20: =Runs!N1263 -> 0 | L20: =Runs!N1274 -> 1 | M20: =Runs!N1285 -> 0 | N20: =Runs!N1296 -> 0 | O20: =Runs!N1307 -> 0 | P20: =Runs!N1318 -> 0 | Q20: =IF(COUNT(G20:P20)=0,"",AVERAGE(G20:P20)) -> 0.2 | R20: =IF(COUNT(G20:P20)<2,"",STDEV(G20:P20)) -> 0.42163702 | S20: =COUNT(G20:P20) -> 10
A21: C02 | B21: FP32 | C21: early | D21: exp_msb | E21: 1 | F21: ship | G21: =Runs!N1220 -> 0 | H21: =Runs!N1231 -> 0 | I21: =Runs!N1242 -> 0 | J21: =Runs!N1253 -> 1 | K21: =Runs!N1264 -> 0 | L21: =Runs!N1275 -> 1 | M21: =Runs!N1286 -> 0 | N21: =Runs!N1297 -> 0 | O21: =Runs!N1308 -> 0 | P21: =Runs!N1319 -> 0 | Q21: =IF(COUNT(G21:P21)=0,"",AVERAGE(G21:P21)) -> 0.2 | R21: =IF(COUNT(G21:P21)<2,"",STDEV(G21:P21)) -> 0.42163702 | S21: =COUNT(G21:P21) -> 10
A22: C02 | B22: FP32 | C22: early | D22: exp_msb | E22: 1 | F22: truck | G22: =Runs!N1221 -> 0.05 | H22: =Runs!N1232 -> 0.05 | I22: =Runs!N1243 -> 0.05 | J22: =Runs!N1254 -> 1 | K22: =Runs!N1265 -> 0.05 | L22: =Runs!N1276 -> 1 | M22: =Runs!N1287 -> 0.05 | N22: =Runs!N1298 -> 0.05 | O22: =Runs!N1309 -> 0.05 | P22: =Runs!N1320 -> 0.05 | Q22: =IF(COUNT(G22:P22)=0,"",AVERAGE(G22:P22)) -> 0.24 | R22: =IF(COUNT(G22:P22)<2,"",STDEV(G22:P22)) -> 0.40055517 | S22: =COUNT(G22:P22) -> 10
A23: C02 | B23: FP32 | C23: early | D23: exp_msb | E23: 1 | F23: ALL | G23: =Runs!N1222 -> 0.005 | H23: =Runs!N1233 -> 0.005 | I23: =Runs!N1244 -> 0.005 | J23: =Runs!N1255 -> 1 | K23: =Runs!N1266 -> 0.005 | L23: =Runs!N1277 -> 1 | M23: =Runs!N1288 -> 0.005 | N23: =Runs!N1299 -> 0.005 | O23: =Runs!N1310 -> 0.005 | P23: =Runs!N1321 -> 0.005 | Q23: =IF(COUNT(G23:P23)=0,"",AVERAGE(G23:P23)) -> 0.204 | R23: =IF(COUNT(G23:P23)<2,"",STDEV(G23:P23)) -> 0.41952884 | S23: =COUNT(G23:P23) -> 10
A24: C03 | B24: FP32 | C24: middle | D24: exp_msb | E24: 4 | F24: airplane | G24: =Runs!N1322 -> 1 | H24: =Runs!N1333 -> 0 | I24: =Runs!N1344 -> 1 | J24: =Runs!N1355 -> 0 | K24: =Runs!N1366 -> 0 | L24: =Runs!N1377 -> 0 | M24: =Runs!N1388 -> 1 | N24: =Runs!N1399 -> 1 | O24: =Runs!N1410 -> 1 | P24: =Runs!N1421 -> 0 | Q24: =IF(COUNT(G24:P24)=0,"",AVERAGE(G24:P24)) -> 0.5 | R24: =IF(COUNT(G24:P24)<2,"",STDEV(G24:P24)) -> 0.52704628 | S24: =COUNT(G24:P24) -> 10
A25: C03 | B25: FP32 | C25: middle | D25: exp_msb | E25: 4 | F25: automobile | G25: =Runs!N1323 -> 1 | H25: =Runs!N1334 -> 0 | I25: =Runs!N1345 -> 1 | J25: =Runs!N1356 -> 0 | K25: =Runs!N1367 -> 0 | L25: =Runs!N1378 -> 0 | M25: =Runs!N1389 -> 1 | N25: =Runs!N1400 -> 1 | O25: =Runs!N1411 -> 1 | P25: =Runs!N1422 -> 0 | Q25: =IF(COUNT(G25:P25)=0,"",AVERAGE(G25:P25)) -> 0.5 | R25: =IF(COUNT(G25:P25)<2,"",STDEV(G25:P25)) -> 0.52704628 | S25: =COUNT(G25:P25) -> 10
A26: C03 | B26: FP32 | C26: middle | D26: exp_msb | E26: 4 | F26: bird | G26: =Runs!N1324 -> 1 | H26: =Runs!N1335 -> 0 | I26: =Runs!N1346 -> 1 | J26: =Runs!N1357 -> 0 | K26: =Runs!N1368 -> 0 | L26: =Runs!N1379 -> 0 | M26: =Runs!N1390 -> 1 | N26: =Runs!N1401 -> 1 | O26: =Runs!N1412 -> 1 | P26: =Runs!N1423 -> 0 | Q26: =IF(COUNT(G26:P26)=0,"",AVERAGE(G26:P26)) -> 0.5 | R26: =IF(COUNT(G26:P26)<2,"",STDEV(G26:P26)) -> 0.52704628 | S26: =COUNT(G26:P26) -> 10
A27: C03 | B27: FP32 | C27: middle | D27: exp_msb | E27: 4 | F27: cat | G27: =Runs!N1325 -> 1 | H27: =Runs!N1336 -> 0 | I27: =Runs!N1347 -> 1 | J27: =Runs!N1358 -> 0 | K27: =Runs!N1369 -> 0 | L27: =Runs!N1380 -> 0 | M27: =Runs!N1391 -> 1 | N27: =Runs!N1402 -> 1 | O27: =Runs!N1413 -> 1 | P27: =Runs!N1424 -> 0 | Q27: =IF(COUNT(G27:P27)=0,"",AVERAGE(G27:P27)) -> 0.5 | R27: =IF(COUNT(G27:P27)<2,"",STDEV(G27:P27)) -> 0.52704628 | S27: =COUNT(G27:P27) -> 10
A28: C03 | B28: FP32 | C28: middle | D28: exp_msb | E28: 4 | F28: deer | G28: =Runs!N1326 -> 1 | H28: =Runs!N1337 -> 0 | I28: =Runs!N1348 -> 1 | J28: =Runs!N1359 -> 0 | K28: =Runs!N1370 -> 0 | L28: =Runs!N1381 -> 0 | M28: =Runs!N1392 -> 1 | N28: =Runs!N1403 -> 1 | O28: =Runs!N1414 -> 1 | P28: =Runs!N1425 -> 0 | Q28: =IF(COUNT(G28:P28)=0,"",AVERAGE(G28:P28)) -> 0.5 | R28: =IF(COUNT(G28:P28)<2,"",STDEV(G28:P28)) -> 0.52704628 | S28: =COUNT(G28:P28) -> 10
A29: C03 | B29: FP32 | C29: middle | D29: exp_msb | E29: 4 | F29: dog | G29: =Runs!N1327 -> 1 | H29: =Runs!N1338 -> 0 | I29: =Runs!N1349 -> 1 | J29: =Runs!N1360 -> 0 | K29: =Runs!N1371 -> 0 | L29: =Runs!N1382 -> 0 | M29: =Runs!N1393 -> 1 | N29: =Runs!N1404 -> 1 | O29: =Runs!N1415 -> 1 | P29: =Runs!N1426 -> 0 | Q29: =IF(COUNT(G29:P29)=0,"",AVERAGE(G29:P29)) -> 0.5 | R29: =IF(COUNT(G29:P29)<2,"",STDEV(G29:P29)) -> 0.52704628 | S29: =COUNT(G29:P29) -> 10
A30: C03 | B30: FP32 | C30: middle | D30: exp_msb | E30: 4 | F30: frog | G30: =Runs!N1328 -> 1 | H30: =Runs!N1339 -> 0 | I30: =Runs!N1350 -> 1 | J30: =Runs!N1361 -> 0 | K30: =Runs!N1372 -> 0 | L30: =Runs!N1383 -> 0 | M30: =Runs!N1394 -> 1 | N30: =Runs!N1405 -> 1 | O30: =Runs!N1416 -> 1 | P30: =Runs!N1427 -> 0 | Q30: =IF(COUNT(G30:P30)=0,"",AVERAGE(G30:P30)) -> 0.5 | R30: =IF(COUNT(G30:P30)<2,"",STDEV(G30:P30)) -> 0.52704628 | S30: =COUNT(G30:P30) -> 10
A31: C03 | B31: FP32 | C31: middle | D31: exp_msb | E31: 4 | F31: horse | G31: =Runs!N1329 -> 1 | H31: =Runs!N1340 -> 0 | I31: =Runs!N1351 -> 1 | J31: =Runs!N1362 -> 0 | K31: =Runs!N1373 -> 0 | L31: =Runs!N1384 -> 0 | M31: =Runs!N1395 -> 1 | N31: =Runs!N1406 -> 1 | O31: =Runs!N1417 -> 1 | P31: =Runs!N1428 -> 0 | Q31: =IF(COUNT(G31:P31)=0,"",AVERAGE(G31:P31)) -> 0.5 | R31: =IF(COUNT(G31:P31)<2,"",STDEV(G31:P31)) -> 0.52704628 | S31: =COUNT(G31:P31) -> 10
A32: C03 | B32: FP32 | C32: middle | D32: exp_msb | E32: 4 | F32: ship | G32: =Runs!N1330 -> 1 | H32: =Runs!N1341 -> 0 | I32: =Runs!N1352 -> 1 | J32: =Runs!N1363 -> 0 | K32: =Runs!N1374 -> 0 | L32: =Runs!N1385 -> 0 | M32: =Runs!N1396 -> 1 | N32: =Runs!N1407 -> 1 | O32: =Runs!N1418 -> 1 | P32: =Runs!N1429 -> 0 | Q32: =IF(COUNT(G32:P32)=0,"",AVERAGE(G32:P32)) -> 0.5 | R32: =IF(COUNT(G32:P32)<2,"",STDEV(G32:P32)) -> 0.52704628 | S32: =COUNT(G32:P32) -> 10
A33: C03 | B33: FP32 | C33: middle | D33: exp_msb | E33: 4 | F33: truck | G33: =Runs!N1331 -> 1 | H33: =Runs!N1342 -> 0.05 | I33: =Runs!N1353 -> 1 | J33: =Runs!N1364 -> 0.05 | K33: =Runs!N1375 -> 0.05 | L33: =Runs!N1386 -> 0.05 | M33: =Runs!N1397 -> 1 | N33: =Runs!N1408 -> 1 | O33: =Runs!N1419 -> 1 | P33: =Runs!N1430 -> 0.05 | Q33: =IF(COUNT(G33:P33)=0,"",AVERAGE(G33:P33)) -> 0.525 | R33: =IF(COUNT(G33:P33)<2,"",STDEV(G33:P33)) -> 0.50069396 | S33: =COUNT(G33:P33) -> 10
A34: C03 | B34: FP32 | C34: middle | D34: exp_msb | E34: 4 | F34: ALL | G34: =Runs!N1332 -> 1 | H34: =Runs!N1343 -> 0.005 | I34: =Runs!N1354 -> 1 | J34: =Runs!N1365 -> 0.005 | K34: =Runs!N1376 -> 0.005 | L34: =Runs!N1387 -> 0.005 | M34: =Runs!N1398 -> 1 | N34: =Runs!N1409 -> 1 | O34: =Runs!N1420 -> 1 | P34: =Runs!N1431 -> 0.005 | Q34: =IF(COUNT(G34:P34)=0,"",AVERAGE(G34:P34)) -> 0.5025 | R34: =IF(COUNT(G34:P34)<2,"",STDEV(G34:P34)) -> 0.52441105 | S34: =COUNT(G34:P34) -> 10
A35: C04 | B35: FP32 | C35: late | D35: exp_msb | E35: 1 | F35: airplane | G35: =Runs!N1432 -> 0 | H35: =Runs!N1443 -> 0 | I35: =Runs!N1454 -> 0 | J35: =Runs!N1465 -> 1 | K35: =Runs!N1476 -> 0 | L35: =Runs!N1487 -> 0 | M35: =Runs!N1498 -> 0 | N35: =Runs!N1509 -> 0 | O35: =Runs!N1520 -> 1 | P35: =Runs!N1531 -> 0 | Q35: =IF(COUNT(G35:P35)=0,"",AVERAGE(G35:P35)) -> 0.2 | R35: =IF(COUNT(G35:P35)<2,"",STDEV(G35:P35)) -> 0.42163702 | S35: =COUNT(G35:P35) -> 10
A36: C04 | B36: FP32 | C36: late | D36: exp_msb | E36: 1 | F36: automobile | G36: =Runs!N1433 -> 0 | H36: =Runs!N1444 -> 0 | I36: =Runs!N1455 -> 0 | J36: =Runs!N1466 -> 1 | K36: =Runs!N1477 -> 0 | L36: =Runs!N1488 -> 0 | M36: =Runs!N1499 -> 0 | N36: =Runs!N1510 -> 0 | O36: =Runs!N1521 -> 1 | P36: =Runs!N1532 -> 0 | Q36: =IF(COUNT(G36:P36)=0,"",AVERAGE(G36:P36)) -> 0.2 | R36: =IF(COUNT(G36:P36)<2,"",STDEV(G36:P36)) -> 0.42163702 | S36: =COUNT(G36:P36) -> 10
A37: C04 | B37: FP32 | C37: late | D37: exp_msb | E37: 1 | F37: bird | G37: =Runs!N1434 -> 0 | H37: =Runs!N1445 -> 0 | I37: =Runs!N1456 -> 0 | J37: =Runs!N1467 -> 1 | K37: =Runs!N1478 -> 0 | L37: =Runs!N1489 -> 0 | M37: =Runs!N1500 -> 0 | N37: =Runs!N1511 -> 0 | O37: =Runs!N1522 -> 1 | P37: =Runs!N1533 -> 0 | Q37: =IF(COUNT(G37:P37)=0,"",AVERAGE(G37:P37)) -> 0.2 | R37: =IF(COUNT(G37:P37)<2,"",STDEV(G37:P37)) -> 0.42163702 | S37: =COUNT(G37:P37) -> 10
A38: C04 | B38: FP32 | C38: late | D38: exp_msb | E38: 1 | F38: cat | G38: =Runs!N1435 -> 0 | H38: =Runs!N1446 -> 0 | I38: =Runs!N1457 -> 0 | J38: =Runs!N1468 -> 1 | K38: =Runs!N1479 -> 0 | L38: =Runs!N1490 -> 0 | M38: =Runs!N1501 -> 0 | N38: =Runs!N1512 -> 0 | O38: =Runs!N1523 -> 1 | P38: =Runs!N1534 -> 0 | Q38: =IF(COUNT(G38:P38)=0,"",AVERAGE(G38:P38)) -> 0.2 | R38: =IF(COUNT(G38:P38)<2,"",STDEV(G38:P38)) -> 0.42163702 | S38: =COUNT(G38:P38) -> 10
A39: C04 | B39: FP32 | C39: late | D39: exp_msb | E39: 1 | F39: deer | G39: =Runs!N1436 -> 0 | H39: =Runs!N1447 -> 0 | I39: =Runs!N1458 -> 0 | J39: =Runs!N1469 -> 1 | K39: =Runs!N1480 -> 0 | L39: =Runs!N1491 -> 0 | M39: =Runs!N1502 -> 0 | N39: =Runs!N1513 -> 0 | O39: =Runs!N1524 -> 0.9 | P39: =Runs!N1535 -> 0 | Q39: =IF(COUNT(G39:P39)=0,"",AVERAGE(G39:P39)) -> 0.19 | R39: =IF(COUNT(G39:P39)<2,"",STDEV(G39:P39)) -> 0.40124805 | S39: =COUNT(G39:P39) -> 10
A40: C04 | B40: FP32 | C40: late | D40: exp_msb | E40: 1 | F40: dog | G40: =Runs!N1437 -> 0 | H40: =Runs!N1448 -> 0 | I40: =Runs!N1459 -> 0 | J40: =Runs!N1470 -> 1 | K40: =Runs!N1481 -> 0 | L40: =Runs!N1492 -> 0 | M40: =Runs!N1503 -> 0 | N40: =Runs!N1514 -> 0 | O40: =Runs!N1525 -> 0.95 | P40: =Runs!N1536 -> 0 | Q40: =IF(COUNT(G40:P40)=0,"",AVERAGE(G40:P40)) -> 0.195 | R40: =IF(COUNT(G40:P40)<2,"",STDEV(G40:P40)) -> 0.41126499 | S40: =COUNT(G40:P40) -> 10
...

Sheet Precision
A1: Config | B1: Format | C1: Where | D1: Which bit | E1: Flips | F1: Class | G1: Rep 1 | H1: Rep 2 | I1: Rep 3 | J1: Rep 4 | K1: Rep 5 | L1: Rep 6 | M1: Rep 7 | N1: Rep 8 | O1: Rep 9 | P1: Rep 10 | Q1: Mean | R1: SD | S1: N
A2: C01 | B2: FP32 | C2: early | D2: sign | E2: 16 | F2: airplane | G2: =Runs!O1102 | H2: =Runs!O1113 | I2: =Runs!O1124 | J2: =Runs!O1135 | K2: =Runs!O1146 | L2: =Runs!O1157 | M2: =Runs!O1168 | N2: =Runs!O1179 | O2: =Runs!O1190 | P2: =Runs!O1201 | Q2: =IF(COUNT(G2:P2)=0,"",AVERAGE(G2:P2)) | R2: =IF(COUNT(G2:P2)<2,"",STDEV(G2:P2)) | S2: =COUNT(G2:P2) -> 0
A3: C01 | B3: FP32 | C3: early | D3: sign | E3: 16 | F3: automobile | G3: =Runs!O1103 -> 1 | H3: =Runs!O1114 | I3: =Runs!O1125 | J3: =Runs!O1136 | K3: =Runs!O1147 | L3: =Runs!O1158 | M3: =Runs!O1169 | N3: =Runs!O1180 | O3: =Runs!O1191 | P3: =Runs!O1202 | Q3: =IF(COUNT(G3:P3)=0,"",AVERAGE(G3:P3)) -> 1 | R3: =IF(COUNT(G3:P3)<2,"",STDEV(G3:P3)) | S3: =COUNT(G3:P3) -> 1
A4: C01 | B4: FP32 | C4: early | D4: sign | E4: 16 | F4: bird | G4: =Runs!O1104 | H4: =Runs!O1115 | I4: =Runs!O1126 | J4: =Runs!O1137 | K4: =Runs!O1148 | L4: =Runs!O1159 | M4: =Runs!O1170 | N4: =Runs!O1181 | O4: =Runs!O1192 | P4: =Runs!O1203 | Q4: =IF(COUNT(G4:P4)=0,"",AVERAGE(G4:P4)) | R4: =IF(COUNT(G4:P4)<2,"",STDEV(G4:P4)) | S4: =COUNT(G4:P4) -> 0
A5: C01 | B5: FP32 | C5: early | D5: sign | E5: 16 | F5: cat | G5: =Runs!O1105 | H5: =Runs!O1116 | I5: =Runs!O1127 | J5: =Runs!O1138 | K5: =Runs!O1149 | L5: =Runs!O1160 | M5: =Runs!O1171 | N5: =Runs!O1182 | O5: =Runs!O1193 | P5: =Runs!O1204 | Q5: =IF(COUNT(G5:P5)=0,"",AVERAGE(G5:P5)) | R5: =IF(COUNT(G5:P5)<2,"",STDEV(G5:P5)) | S5: =COUNT(G5:P5) -> 0
A6: C01 | B6: FP32 | C6: early | D6: sign | E6: 16 | F6: deer | G6: =Runs!O1106 | H6: =Runs!O1117 | I6: =Runs!O1128 | J6: =Runs!O1139 | K6: =Runs!O1150 | L6: =Runs!O1161 | M6: =Runs!O1172 | N6: =Runs!O1183 | O6: =Runs!O1194 | P6: =Runs!O1205 | Q6: =IF(COUNT(G6:P6)=0,"",AVERAGE(G6:P6)) | R6: =IF(COUNT(G6:P6)<2,"",STDEV(G6:P6)) | S6: =COUNT(G6:P6) -> 0
A7: C01 | B7: FP32 | C7: early | D7: sign | E7: 16 | F7: dog | G7: =Runs!O1107 | H7: =Runs!O1118 | I7: =Runs!O1129 | J7: =Runs!O1140 | K7: =Runs!O1151 | L7: =Runs!O1162 | M7: =Runs!O1173 | N7: =Runs!O1184 | O7: =Runs!O1195 | P7: =Runs!O1206 | Q7: =IF(COUNT(G7:P7)=0,"",AVERAGE(G7:P7)) | R7: =IF(COUNT(G7:P7)<2,"",STDEV(G7:P7)) | S7: =COUNT(G7:P7) -> 0
A8: C01 | B8: FP32 | C8: early | D8: sign | E8: 16 | F8: frog | G8: =Runs!O1108 | H8: =Runs!O1119 | I8: =Runs!O1130 | J8: =Runs!O1141 | K8: =Runs!O1152 -> 1 | L8: =Runs!O1163 | M8: =Runs!O1174 | N8: =Runs!O1185 -> 1 | O8: =Runs!O1196 -> 1 | P8: =Runs!O1207 | Q8: =IF(COUNT(G8:P8)=0,"",AVERAGE(G8:P8)) -> 1 | R8: =IF(COUNT(G8:P8)<2,"",STDEV(G8:P8)) -> 0 | S8: =COUNT(G8:P8) -> 3
A9: C01 | B9: FP32 | C9: early | D9: sign | E9: 16 | F9: horse | G9: =Runs!O1109 | H9: =Runs!O1120 | I9: =Runs!O1131 | J9: =Runs!O1142 | K9: =Runs!O1153 | L9: =Runs!O1164 | M9: =Runs!O1175 | N9: =Runs!O1186 | O9: =Runs!O1197 | P9: =Runs!O1208 | Q9: =IF(COUNT(G9:P9)=0,"",AVERAGE(G9:P9)) | R9: =IF(COUNT(G9:P9)<2,"",STDEV(G9:P9)) | S9: =COUNT(G9:P9) -> 0
A10: C01 | B10: FP32 | C10: early | D10: sign | E10: 16 | F10: ship | G10: =Runs!O1110 | H10: =Runs!O1121 | I10: =Runs!O1132 | J10: =Runs!O1143 | K10: =Runs!O1154 | L10: =Runs!O1165 | M10: =Runs!O1176 | N10: =Runs!O1187 | O10: =Runs!O1198 | P10: =Runs!O1209 | Q10: =IF(COUNT(G10:P10)=0,"",AVERAGE(G10:P10)) | R10: =IF(COUNT(G10:P10)<2,"",STDEV(G10:P10)) | S10: =COUNT(G10:P10) -> 0
A11: C01 | B11: FP32 | C11: early | D11: sign | E11: 16 | F11: truck | G11: =Runs!O1111 -> 0 | H11: =Runs!O1122 -> 0.5 | I11: =Runs!O1133 -> 0.5 | J11: =Runs!O1144 -> 0.5 | K11: =Runs!O1155 -> 0.5 | L11: =Runs!O1166 -> 0 | M11: =Runs!O1177 -> 0.5 | N11: =Runs!O1188 -> 0 | O11: =Runs!O1199 -> 0.5 | P11: =Runs!O1210 -> 0.5 | Q11: =IF(COUNT(G11:P11)=0,"",AVERAGE(G11:P11)) -> 0.35 | R11: =IF(COUNT(G11:P11)<2,"",STDEV(G11:P11)) -> 0.24152295 | S11: =COUNT(G11:P11) -> 10
A12: C01 | B12: FP32 | C12: early | D12: sign | E12: 16 | F12: ALL | G12: =Runs!O1112 -> 0.5 | H12: =Runs!O1123 -> 0.5 | I12: =Runs!O1134 -> 0.5 | J12: =Runs!O1145 -> 0.5 | K12: =Runs!O1156 -> 0.66666667 | L12: =Runs!O1167 -> 0 | M12: =Runs!O1178 -> 0.5 | N12: =Runs!O1189 -> 0.5 | O12: =Runs!O1200 -> 0.66666667 | P12: =Runs!O1211 -> 0.5 | Q12: =IF(COUNT(G12:P12)=0,"",AVERAGE(G12:P12)) -> 0.48333333 | R12: =IF(COUNT(G12:P12)<2,"",STDEV(G12:P12)) -> 0.18341749 | S12: =COUNT(G12:P12) -> 10
A13: C02 | B13: FP32 | C13: early | D13: exp_msb | E13: 1 | F13: airplane | G13: =Runs!O1212 | H13: =Runs!O1223 | I13: =Runs!O1234 | J13: =Runs!O1245 -> 1 | K13: =Runs!O1256 | L13: =Runs!O1267 -> 1 | M13: =Runs!O1278 | N13: =Runs!O1289 | O13: =Runs!O1300 | P13: =Runs!O1311 | Q13: =IF(COUNT(G13:P13)=0,"",AVERAGE(G13:P13)) -> 1 | R13: =IF(COUNT(G13:P13)<2,"",STDEV(G13:P13)) -> 0 | S13: =COUNT(G13:P13) -> 2
A14: C02 | B14: FP32 | C14: early | D14: exp_msb | E14: 1 | F14: automobile | G14: =Runs!O1213 | H14: =Runs!O1224 | I14: =Runs!O1235 | J14: =Runs!O1246 -> 1 | K14: =Runs!O1257 | L14: =Runs!O1268 -> 1 | M14: =Runs!O1279 | N14: =Runs!O1290 | O14: =Runs!O1301 | P14: =Runs!O1312 | Q14: =IF(COUNT(G14:P14)=0,"",AVERAGE(G14:P14)) -> 1 | R14: =IF(COUNT(G14:P14)<2,"",STDEV(G14:P14)) -> 0 | S14: =COUNT(G14:P14) -> 2
A15: C02 | B15: FP32 | C15: early | D15: exp_msb | E15: 1 | F15: bird | G15: =Runs!O1214 | H15: =Runs!O1225 | I15: =Runs!O1236 | J15: =Runs!O1247 -> 1 | K15: =Runs!O1258 | L15: =Runs!O1269 -> 1 | M15: =Runs!O1280 | N15: =Runs!O1291 | O15: =Runs!O1302 | P15: =Runs!O1313 | Q15: =IF(COUNT(G15:P15)=0,"",AVERAGE(G15:P15)) -> 1 | R15: =IF(COUNT(G15:P15)<2,"",STDEV(G15:P15)) -> 0 | S15: =COUNT(G15:P15) -> 2
A16: C02 | B16: FP32 | C16: early | D16: exp_msb | E16: 1 | F16: cat | G16: =Runs!O1215 | H16: =Runs!O1226 | I16: =Runs!O1237 | J16: =Runs!O1248 -> 1 | K16: =Runs!O1259 | L16: =Runs!O1270 -> 1 | M16: =Runs!O1281 | N16: =Runs!O1292 | O16: =Runs!O1303 | P16: =Runs!O1314 | Q16: =IF(COUNT(G16:P16)=0,"",AVERAGE(G16:P16)) -> 1 | R16: =IF(COUNT(G16:P16)<2,"",STDEV(G16:P16)) -> 0 | S16: =COUNT(G16:P16) -> 2
A17: C02 | B17: FP32 | C17: early | D17: exp_msb | E17: 1 | F17: deer | G17: =Runs!O1216 | H17: =Runs!O1227 | I17: =Runs!O1238 | J17: =Runs!O1249 -> 1 | K17: =Runs!O1260 | L17: =Runs!O1271 -> 1 | M17: =Runs!O1282 | N17: =Runs!O1293 | O17: =Runs!O1304 | P17: =Runs!O1315 | Q17: =IF(COUNT(G17:P17)=0,"",AVERAGE(G17:P17)) -> 1 | R17: =IF(COUNT(G17:P17)<2,"",STDEV(G17:P17)) -> 0 | S17: =COUNT(G17:P17) -> 2
A18: C02 | B18: FP32 | C18: early | D18: exp_msb | E18: 1 | F18: dog | G18: =Runs!O1217 | H18: =Runs!O1228 | I18: =Runs!O1239 | J18: =Runs!O1250 -> 1 | K18: =Runs!O1261 | L18: =Runs!O1272 -> 1 | M18: =Runs!O1283 | N18: =Runs!O1294 | O18: =Runs!O1305 | P18: =Runs!O1316 | Q18: =IF(COUNT(G18:P18)=0,"",AVERAGE(G18:P18)) -> 1 | R18: =IF(COUNT(G18:P18)<2,"",STDEV(G18:P18)) -> 0 | S18: =COUNT(G18:P18) -> 2
A19: C02 | B19: FP32 | C19: early | D19: exp_msb | E19: 1 | F19: frog | G19: =Runs!O1218 | H19: =Runs!O1229 | I19: =Runs!O1240 | J19: =Runs!O1251 -> 1 | K19: =Runs!O1262 | L19: =Runs!O1273 -> 1 | M19: =Runs!O1284 | N19: =Runs!O1295 | O19: =Runs!O1306 | P19: =Runs!O1317 | Q19: =IF(COUNT(G19:P19)=0,"",AVERAGE(G19:P19)) -> 1 | R19: =IF(COUNT(G19:P19)<2,"",STDEV(G19:P19)) -> 0 | S19: =COUNT(G19:P19) -> 2
A20: C02 | B20: FP32 | C20: early | D20: exp_msb | E20: 1 | F20: horse | G20: =Runs!O1219 | H20: =Runs!O1230 | I20: =Runs!O1241 | J20: =Runs!O1252 -> 1 | K20: =Runs!O1263 | L20: =Runs!O1274 -> 1 | M20: =Runs!O1285 | N20: =Runs!O1296 | O20: =Runs!O1307 | P20: =Runs!O1318 | Q20: =IF(COUNT(G20:P20)=0,"",AVERAGE(G20:P20)) -> 1 | R20: =IF(COUNT(G20:P20)<2,"",STDEV(G20:P20)) -> 0 | S20: =COUNT(G20:P20) -> 2
A21: C02 | B21: FP32 | C21: early | D21: exp_msb | E21: 1 | F21: ship | G21: =Runs!O1220 | H21: =Runs!O1231 | I21: =Runs!O1242 | J21: =Runs!O1253 -> 1 | K21: =Runs!O1264 | L21: =Runs!O1275 -> 1 | M21: =Runs!O1286 | N21: =Runs!O1297 | O21: =Runs!O1308 | P21: =Runs!O1319 | Q21: =IF(COUNT(G21:P21)=0,"",AVERAGE(G21:P21)) -> 1 | R21: =IF(COUNT(G21:P21)<2,"",STDEV(G21:P21)) -> 0 | S21: =COUNT(G21:P21) -> 2
A22: C02 | B22: FP32 | C22: early | D22: exp_msb | E22: 1 | F22: truck | G22: =Runs!O1221 -> 0.5 | H22: =Runs!O1232 -> 0.5 | I22: =Runs!O1243 -> 0.5 | J22: =Runs!O1254 -> 0.95238095 | K22: =Runs!O1265 -> 0.5 | L22: =Runs!O1276 -> 0.95238095 | M22: =Runs!O1287 -> 0.5 | N22: =Runs!O1298 -> 0.5 | O22: =Runs!O1309 -> 0.5 | P22: =Runs!O1320 -> 0.5 | Q22: =IF(COUNT(G22:P22)=0,"",AVERAGE(G22:P22)) -> 0.59047619 | R22: =IF(COUNT(G22:P22)<2,"",STDEV(G22:P22)) -> 0.19074056 | S22: =COUNT(G22:P22) -> 10
A23: C02 | B23: FP32 | C23: early | D23: exp_msb | E23: 1 | F23: ALL | G23: =Runs!O1222 -> 0.5 | H23: =Runs!O1233 -> 0.5 | I23: =Runs!O1244 -> 0.5 | J23: =Runs!O1255 -> 0.99502488 | K23: =Runs!O1266 -> 0.5 | L23: =Runs!O1277 -> 0.99502488 | M23: =Runs!O1288 -> 0.5 | N23: =Runs!O1299 -> 0.5 | O23: =Runs!O1310 -> 0.5 | P23: =Runs!O1321 -> 0.5 | Q23: =IF(COUNT(G23:P23)=0,"",AVERAGE(G23:P23)) -> 0.59900498 | R23: =IF(COUNT(G23:P23)<2,"",STDEV(G23:P23)) -> 0.20872081 | S23: =COUNT(G23:P23) -> 10
A24: C03 | B24: FP32 | C24: middle | D24: exp_msb | E24: 4 | F24: airplane | G24: =Runs!O1322 -> 1 | H24: =Runs!O1333 | I24: =Runs!O1344 -> 1 | J24: =Runs!O1355 | K24: =Runs!O1366 | L24: =Runs!O1377 | M24: =Runs!O1388 -> 1 | N24: =Runs!O1399 -> 1 | O24: =Runs!O1410 -> 1 | P24: =Runs!O1421 | Q24: =IF(COUNT(G24:P24)=0,"",AVERAGE(G24:P24)) -> 1 | R24: =IF(COUNT(G24:P24)<2,"",STDEV(G24:P24)) -> 0 | S24: =COUNT(G24:P24) -> 5
A25: C03 | B25: FP32 | C25: middle | D25: exp_msb | E25: 4 | F25: automobile | G25: =Runs!O1323 -> 1 | H25: =Runs!O1334 | I25: =Runs!O1345 -> 1 | J25: =Runs!O1356 | K25: =Runs!O1367 | L25: =Runs!O1378 | M25: =Runs!O1389 -> 1 | N25: =Runs!O1400 -> 1 | O25: =Runs!O1411 -> 1 | P25: =Runs!O1422 | Q25: =IF(COUNT(G25:P25)=0,"",AVERAGE(G25:P25)) -> 1 | R25: =IF(COUNT(G25:P25)<2,"",STDEV(G25:P25)) -> 0 | S25: =COUNT(G25:P25) -> 5
A26: C03 | B26: FP32 | C26: middle | D26: exp_msb | E26: 4 | F26: bird | G26: =Runs!O1324 -> 1 | H26: =Runs!O1335 | I26: =Runs!O1346 -> 1 | J26: =Runs!O1357 | K26: =Runs!O1368 | L26: =Runs!O1379 | M26: =Runs!O1390 -> 1 | N26: =Runs!O1401 -> 1 | O26: =Runs!O1412 -> 1 | P26: =Runs!O1423 | Q26: =IF(COUNT(G26:P26)=0,"",AVERAGE(G26:P26)) -> 1 | R26: =IF(COUNT(G26:P26)<2,"",STDEV(G26:P26)) -> 0 | S26: =COUNT(G26:P26) -> 5
A27: C03 | B27: FP32 | C27: middle | D27: exp_msb | E27: 4 | F27: cat | G27: =Runs!O1325 -> 1 | H27: =Runs!O1336 | I27: =Runs!O1347 -> 1 | J27: =Runs!O1358 | K27: =Runs!O1369 | L27: =Runs!O1380 | M27: =Runs!O1391 -> 1 | N27: =Runs!O1402 -> 1 | O27: =Runs!O1413 -> 1 | P27: =Runs!O1424 | Q27: =IF(COUNT(G27:P27)=0,"",AVERAGE(G27:P27)) -> 1 | R27: =IF(COUNT(G27:P27)<2,"",STDEV(G27:P27)) -> 0 | S27: =COUNT(G27:P27) -> 5
A28: C03 | B28: FP32 | C28: middle | D28: exp_msb | E28: 4 | F28: deer | G28: =Runs!O1326 -> 1 | H28: =Runs!O1337 | I28: =Runs!O1348 -> 1 | J28: =Runs!O1359 | K28: =Runs!O1370 | L28: =Runs!O1381 | M28: =Runs!O1392 -> 1 | N28: =Runs!O1403 -> 1 | O28: =Runs!O1414 -> 1 | P28: =Runs!O1425 | Q28: =IF(COUNT(G28:P28)=0,"",AVERAGE(G28:P28)) -> 1 | R28: =IF(COUNT(G28:P28)<2,"",STDEV(G28:P28)) -> 0 | S28: =COUNT(G28:P28) -> 5
A29: C03 | B29: FP32 | C29: middle | D29: exp_msb | E29: 4 | F29: dog | G29: =Runs!O1327 -> 1 | H29: =Runs!O1338 | I29: =Runs!O1349 -> 1 | J29: =Runs!O1360 | K29: =Runs!O1371 | L29: =Runs!O1382 | M29: =Runs!O1393 -> 1 | N29: =Runs!O1404 -> 1 | O29: =Runs!O1415 -> 1 | P29: =Runs!O1426 | Q29: =IF(COUNT(G29:P29)=0,"",AVERAGE(G29:P29)) -> 1 | R29: =IF(COUNT(G29:P29)<2,"",STDEV(G29:P29)) -> 0 | S29: =COUNT(G29:P29) -> 5
A30: C03 | B30: FP32 | C30: middle | D30: exp_msb | E30: 4 | F30: frog | G30: =Runs!O1328 -> 1 | H30: =Runs!O1339 | I30: =Runs!O1350 -> 1 | J30: =Runs!O1361 | K30: =Runs!O1372 | L30: =Runs!O1383 | M30: =Runs!O1394 -> 1 | N30: =Runs!O1405 -> 1 | O30: =Runs!O1416 -> 1 | P30: =Runs!O1427 | Q30: =IF(COUNT(G30:P30)=0,"",AVERAGE(G30:P30)) -> 1 | R30: =IF(COUNT(G30:P30)<2,"",STDEV(G30:P30)) -> 0 | S30: =COUNT(G30:P30) -> 5
